Workbook

Sheet combined
A1: feature extraction | B1: batch size | C1: learning rate | D1: epochs | E1: msg per input | F1: bfw | G1: auc | H1: max f1 | I1: max f1 threshhold | J1: config ID | K1: Tie Threshold | L1: Wins | M1: Loss | O1: Best AUC
A2: 1 | B2: 1024 | C2: 0.0018 | D2: 1000 | E2: 192 | F2: 1 | G2: 0.87364046 | H2: 0.12448133 | I2: 0.54392657 | J2: =A2 & "_" & B2 & "_" & C2 & "_" & D2 & "_" & E2 -> 1_1024_0.0018_1000_192 | K2: {=IF(F2=1, H2 - _xlfn.XLOOKUP(1, (J:J=J2)*(F:F=0), H:H), _xlfn.XLOOKUP(1, (J:J=J2)*(F:F=1), H:H) - H2 )} -> 0.0080005347 | L2: =IF(AND(F2=1, K2 > $N$2), 1, 0) -> 1 | M2: =IF(AND(F2=1, K2 < -$N$2), 1, 0) -> 0 | N2: 0.002 | O2: feature extraction | P2: batch size | Q2: learning rate | R2: epochs | S2: msg per input | T2: bfw | U2: auc | V2: max f1 | W2: max f1 threshhold | X2: config ID | Y2: Tie Threshold
A3: 1 | B3: 1024 | C3: 0.0018 | D3: 1000 | E3: 192 | F3: 1 | G3: 0.87312799 | H3: 0.12396694 | I3: 0.54266989 | J3: =A3 & "_" & B3 & "_" & C3 & "_" & D3 & "_" & E3 -> 1_1024_0.0018_1000_192 | K3: {=IF(F3=1, H3 - _xlfn.XLOOKUP(1, (J:J=J3)*(F:F=0), H:H), _xlfn.XLOOKUP(1, (J:J=J3)*(F:F=1), H:H) - H3 )} -> 0.0074861491 | L3: =IF(AND(F3=1, K3 > $N$2), 1, 0) -> 1 | M3: =IF(AND(F3=1, K3 < -$N$2), 1, 0) -> 0 | O3: {=_xlfn.XLOOKUP(MAX(G:G), G:G, A:A:K:K)} -> 1 | P3: 512 | Q3: 0.002 | R3: 1000 | S3: 256 | T3: 1 | U3: 0.93214677 | V3: 0.18867925 | W3: 1.3812735 | X3: 1_512_0.002_1000_256 | Y3: 0.028835191
A4: 1 | B4: 1024 | C4: 0.0018 | D4: 1000 | E4: 192 | F4: 1 | G4: 0.87302233 | H4: 0.12465374 | I4: 0.54328243 | J4: =A4 & "_" & B4 & "_" & C4 & "_" & D4 & "_" & E4 -> 1_1024_0.0018_1000_192 | K4: {=IF(F4=1, H4 - _xlfn.XLOOKUP(1, (J:J=J4)*(F:F=0), H:H), _xlfn.XLOOKUP(1, (J:J=J4)*(F:F=1), H:H) - H4 )} -> 0.0081729466 | L4: =IF(AND(F4=1, K4 > $N$2), 1, 0) -> 1 | M4: =IF(AND(F4=1, K4 < -$N$2), 1, 0) -> 0 | O4: Best F1
A5: 1 | B5: 1024 | C5: 0.0018 | D5: 1000 | E5: 192 | F5: 0 | G5: 0.86589708 | H5: 0.11648079 | I5: 0.50726321 | J5: =A5 & "_" & B5 & "_" & C5 & "_" & D5 & "_" & E5 -> 1_1024_0.0018_1000_192 | K5: {=IF(F5=1, H5 - _xlfn.XLOOKUP(1, (J:J=J5)*(F:F=0), H:H), _xlfn.XLOOKUP(1, (J:J=J5)*(F:F=1), H:H) - H5 )} -> 0.0080005347 | L5: =IF(AND(F5=1, K5 > $N$2), 1, 0) -> 0 | M5: =IF(AND(F5=1, K5 < -$N$2), 1, 0) -> 0 | O5: {=_xlfn.XLOOKUP(MAX(H:H), H:H, A:A:K:K)} -> 1 | P5: 512 | Q5: 0.002 | R5: 1000 | S5: 256 | T5: 1 | U5: 0.93214677 | V5: 0.18867925 | W5: 1.3812735 | X5: 1_512_0.002_1000_256 | Y5: 0.028835191
A6: 1 | B6: 1024 | C6: 0.002 | D6: 1000 | E6: 192 | F6: 1 | G6: 0.88123943 | H6: 0.13024602 | I6: 0.58466298 | J6: =A6 & "_" & B6 & "_" & C6 & "_" & D6 & "_" & E6 -> 1_1024_0.002_1000_192 | K6: {=IF(F6=1, H6 - _xlfn.XLOOKUP(1, (J:J=J6)*(F:F=0), H:H), _xlfn.XLOOKUP(1, (J:J=J6)*(F:F=1), H:H) - H6 )} -> 0.0047344241 | L6: =IF(AND(F6=1, K6 > $N$2), 1, 0) -> 1 | M6: =IF(AND(F6=1, K6 < -$N$2), 1, 0) -> 0
A7: 1 | B7: 1024 | C7: 0.0025 | D7: 1000 | E7: 192 | F7: 1 | G7: 0.88062482 | H7: 0.1325811 | I7: 0.56031811 | J7: =A7 & "_" & B7 & "_" & C7 & "_" & D7 & "_" & E7 -> 1_1024_0.0025_1000_192 | K7: {=IF(F7=1, H7 - _xlfn.XLOOKUP(1, (J:J=J7)*(F:F=0), H:H), _xlfn.XLOOKUP(1, (J:J=J7)*(F:F=1), H:H) - H7 )} -> 0.010661515 | L7: =IF(AND(F7=1, K7 > $N$2), 1, 0) -> 1 | M7: =IF(AND(F7=1, K7 < -$N$2), 1, 0) -> 0 | O7: Average AUC with BFW | Q7: Average AUC without BFW | S7: Difference in AUC mean with BFW - without BFW
A8: 1 | B8: 1024 | C8: 0.0025 | D8: 1000 | E8: 192 | F8: 0 | G8: 0.87086855 | H8: 0.12191958 | I8: 0.51598738 | J8: =A8 & "_" & B8 & "_" & C8 & "_" & D8 & "_" & E8 -> 1_1024_0.0025_1000_192 | K8: {=IF(F8=1, H8 - _xlfn.XLOOKUP(1, (J:J=J8)*(F:F=0), H:H), _xlfn.XLOOKUP(1, (J:J=J8)*(F:F=1), H:H) - H8 )} -> 0.010661515 | L8: =IF(AND(F8=1, K8 > $N$2), 1, 0) -> 0 | M8: =IF(AND(F8=1, K8 < -$N$2), 1, 0) -> 0 | O8: =AVERAGEIF(F:F, 1, G:G) -> 0.82609576 | Q8: =AVERAGEIF(F:F, 0, G:G) -> 0.81653984 | S8: =O8-Q8 -> 0.0095559262
A9: 1 | B9: 1024 | C9: 0.002 | D9: 1000 | E9: 192 | F9: 0 | G9: 0.87448401 | H9: 0.1255116 | I9: 0.53182276 | J9: =A9 & "_" & B9 & "_" & C9 & "_" & D9 & "_" & E9 -> 1_1024_0.002_1000_192 | K9: {=IF(F9=1, H9 - _xlfn.XLOOKUP(1, (J:J=J9)*(F:F=0), H:H), _xlfn.XLOOKUP(1, (J:J=J9)*(F:F=1), H:H) - H9 )} -> 0.0047344241 | L9: =IF(AND(F9=1, K9 > $N$2), 1, 0) -> 0 | M9: =IF(AND(F9=1, K9 < -$N$2), 1, 0) -> 0
A10: 1 | B10: 1024 | C10: 0.0018 | D10: 1000 | E10: 224 | F10: 1 | G10: 0.88500631 | H10: 0.14285714 | I10: 0.59176155 | J10: =A10 & "_" & B10 & "_" & C10 & "_" & D10 & "_" & E10 -> 1_1024_0.0018_1000_224 | K10: {=IF(F10=1, H10 - _xlfn.XLOOKUP(1, (J:J=J10)*(F:F=0), H:H), _xlfn.XLOOKUP(1, (J:J=J10)*(F:F=1), H:H) - H10 )} -> 0.0086917762 | L10: =IF(AND(F10=1, K10 > $N$2), 1, 0) -> 1 | M10: =IF(AND(F10=1, K10 < -$N$2), 1, 0) -> 0 | O10: AUC Mean T Test p-value | Q10: Percent Improvement in AUC mean with BFW
A11: 1 | B11: 1024 | C11: 0.0018 | D11: 1000 | E11: 224 | F11: 0 | G11: 0.8799364 | H11: 0.13416537 | I11: 0.53742472 | J11: =A11 & "_" & B11 & "_" & C11 & "_" & D11 & "_" & E11 -> 1_1024_0.0018_1000_224 | K11: {=IF(F11=1, H11 - _xlfn.XLOOKUP(1, (J:J=J11)*(F:F=0), H:H), _xlfn.XLOOKUP(1, (J:J=J11)*(F:F=1), H:H) - H11 )} -> 0.0086917762 | L11: =IF(AND(F11=1, K11 > $N$2), 1, 0) -> 0 | M11: =IF(AND(F11=1, K11 < -$N$2), 1, 0) -> 0 | O11: {=_xlfn.T.TEST(_xlfn._xlws.FILTER(G:G, F:F=1), _xlfn._xlws.FILTER(G:G, F:F=0), 2, 3)} -> 0.76154837 | Q11: =(S8)/Q8*100 -> 1.1702952
A12: 1 | B12: 1024 | C12: 0.002 | D12: 1000 | E12: 224 | F12: 1 | G12: 0.8878385 | H12: 0.14488189 | I12: 0.54592661 | J12: =A12 & "_" & B12 & "_" & C12 & "_" & D12 & "_" & E12 -> 1_1024_0.002_1000_224 | K12: {=IF(F12=1, H12 - _xlfn.XLOOKUP(1, (J:J=J12)*(F:F=0), H:H), _xlfn.XLOOKUP(1, (J:J=J12)*(F:F=1), H:H) - H12 )} -> -0.0027906624 | L12: =IF(AND(F12=1, K12 > $N$2), 1, 0) -> 0 | M12: =IF(AND(F12=1, K12 < -$N$2), 1, 0) -> 1
A13: 1 | B13: 1024 | C13: 0.0025 | D13: 1000 | E13: 224 | F13: 1 | G13: 0.88769592 | H13: 0.14681892 | I13: 0.55315614 | J13: =A13 & "_" & B13 & "_" & C13 & "_" & D13 & "_" & E13 -> 1_1024_0.0025_1000_224 | K13: {=IF(F13=1, H13 - _xlfn.XLOOKUP(1, (J:J=J13)*(F:F=0), H:H), _xlfn.XLOOKUP(1, (J:J=J13)*(F:F=1), H:H) - H13 )} -> 0.0069379709 | L13: =IF(AND(F13=1, K13 > $N$2), 1, 0) -> 1 | M13: =IF(AND(F13=1, K13 < -$N$2), 1, 0) -> 0 | O13: Average F1 with BFW | Q13: Average F1 without BFW | S13: Difference in F1 mean with BFW - without BFW
A14: 1 | B14: 1024 | C14: 0.0025 | D14: 1000 | E14: 224 | F14: 0 | G14: 0.88072177 | H14: 0.13988095 | I14: 0.52650788 | J14: =A14 & "_" & B14 & "_" & C14 & "_" & D14 & "_" & E14 -> 1_1024_0.0025_1000_224 | K14: {=IF(F14=1, H14 - _xlfn.XLOOKUP(1, (J:J=J14)*(F:F=0), H:H), _xlfn.XLOOKUP(1, (J:J=J14)*(F:F=1), H:H) - H14 )} -> 0.0069379709 | L14: =IF(AND(F14=1, K14 > $N$2), 1, 0) -> 0 | M14: =IF(AND(F14=1, K14 < -$N$2), 1, 0) -> 0 | O14: =AVERAGEIF(F:F, 1, H:H) -> 0.11797939 | Q14: =AVERAGEIF(F:F, 0, H:H) -> 0.111959 | S14: =O14-Q14 -> 0.0060203876
A15: 1 | B15: 1024 | C15: 0.002 | D15: 1000 | E15: 224 | F15: 0 | G15: 0.89040003 | H15: 0.14767255 | I15: 0.54567521 | J15: =A15 & "_" & B15 & "_" & C15 & "_" & D15 & "_" & E15 -> 1_1024_0.002_1000_224 | K15: {=IF(F15=1, H15 - _xlfn.XLOOKUP(1, (J:J=J15)*(F:F=0), H:H), _xlfn.XLOOKUP(1, (J:J=J15)*(F:F=1), H:H) - H15 )} -> -0.0027906624 | L15: =IF(AND(F15=1, K15 > $N$2), 1, 0) -> 0 | M15: =IF(AND(F15=1, K15 < -$N$2), 1, 0) -> 0
A16: 1 | B16: 256 | C16: 0.0018 | D16: 1000 | E16: 192 | F16: 1 | G16: 0.87939737 | H16: 0.1296061 | I16: 0.51235213 | J16: =A16 & "_" & B16 & "_" & C16 & "_" & D16 & "_" & E16 -> 1_256_0.0018_1000_192 | K16: {=IF(F16=1, H16 - _xlfn.XLOOKUP(1, (J:J=J16)*(F:F=0), H:H), _xlfn.XLOOKUP(1, (J:J=J16)*(F:F=1), H:H) - H16 )} -> 0.010499399 | L16: =IF(AND(F16=1, K16 > $N$2), 1, 0) -> 1 | M16: =IF(AND(F16=1, K16 < -$N$2), 1, 0) -> 0 | O16: F1 Mean T Test p-value | Q16: Percent Improvement in AUC mean with BFW
A17: 1 | B17: 256 | C17: 0.0018 | D17: 1000 | E17: 192 | F17: 0 | G17: 0.86816885 | H17: 0.1191067 | I17: 0.50138964 | J17: =A17 & "_" & B17 & "_" & C17 & "_" & D17 & "_" & E17 -> 1_256_0.0018_1000_192 | K17: {=IF(F17=1, H17 - _xlfn.XLOOKUP(1, (J:J=J17)*(F:F=0), H:H), _xlfn.XLOOKUP(1, (J:J=J17)*(F:F=1), H:H) - H17 )} -> 0.010499399 | L17: =IF(AND(F17=1, K17 > $N$2), 1, 0) -> 0 | M17: =IF(AND(F17=1, K17 < -$N$2), 1, 0) -> 0 | O17: {=_xlfn.T.TEST(_xlfn._xlws.FILTER(H:H, F:F=1), _xlfn._xlws.FILTER(H:H, F:F=0), 2, 3)} -> 0.5907157 | Q17: =(S14)/Q14*100 -> 5.3773143
A18: 1 | B18: 256 | C18: 0.002 | D18: 1000 | E18: 192 | F18: 1 | G18: 0.88116723 | H18: 0.1319797 | I18: 0.51412949 | J18: =A18 & "_" & B18 & "_" & C18 & "_" & D18 & "_" & E18 -> 1_256_0.002_1000_192 | K18: {=IF(F18=1, H18 - _xlfn.XLOOKUP(1, (J:J=J18)*(F:F=0), H:H), _xlfn.XLOOKUP(1, (J:J=J18)*(F:F=1), H:H) - H18 )} -> 0.00065274605 | L18: =IF(AND(F18=1, K18 > $N$2), 1, 0) -> 0 | M18: =IF(AND(F18=1, K18 < -$N$2), 1, 0) -> 0
A19: 1 | B19: 256 | C19: 0.0025 | D19: 1000 | E19: 192 | F19: 1 | G19: 0.87697591 | H19: 0.12848485 | I19: 0.49881924 | J19: =A19 & "_" & B19 & "_" & C19 & "_" & D19 & "_" & E19 -> 1_256_0.0025_1000_192 | K19: {=IF(F19=1, H19 - _xlfn.XLOOKUP(1, (J:J=J19)*(F:F=0), H:H), _xlfn.XLOOKUP(1, (J:J=J19)*(F:F=1), H:H) - H19 )} -> 0.004106739 | L19: =IF(AND(F19=1, K19 > $N$2), 1, 0) -> 1 | M19: =IF(AND(F19=1, K19 < -$N$2), 1, 0) -> 0
A20: 1 | B20: 256 | C20: 0.0025 | D20: 1000 | E20: 192 | F20: 0 | G20: 0.87202381 | H20: 0.12437811 | I20: 0.50407391 | J20: =A20 & "_" & B20 & "_" & C20 & "_" & D20 & "_" & E20 -> 1_256_0.0025_1000_192 | K20: {=IF(F20=1, H20 - _xlfn.XLOOKUP(1, (J:J=J20)*(F:F=0), H:H), _xlfn.XLOOKUP(1, (J:J=J20)*(F:F=1), H:H) - H20 )} -> 0.004106739 | L20: =IF(AND(F20=1, K20 > $N$2), 1, 0) -> 0 | M20: =IF(AND(F20=1, K20 < -$N$2), 1, 0) -> 0 | O20: =O7 -> Average AUC with BFW | P20: =Q7 -> Average AUC without BFW | Q20: =S7 -> Difference in AUC mean with BFW - without BFW | R20: =O10 -> AUC Mean T Test p-value | S20: =Q10 -> Percent Improvement in AUC mean with BFW
A21: 1 | B21: 256 | C21: 0.002 | D21: 1000 | E21: 192 | F21: 0 | G21: 0.87936567 | H21: 0.13132695 | I21: 0.52721865 | J21: =A21 & "_" & B21 & "_" & C21 & "_" & D21 & "_" & E21 -> 1_256_0.002_1000_192 | K21: {=IF(F21=1, H21 - _xlfn.XLOOKUP(1, (J:J=J21)*(F:F=0), H:H), _xlfn.XLOOKUP(1, (J:J=J21)*(F:F=1), H:H) - H21 )} -> 0.00065274605 | L21: =IF(AND(F21=1, K21 > $N$2), 1, 0) -> 0 | M21: =IF(AND(F21=1, K21 < -$N$2), 1, 0) -> 0 | O21: =O8 -> 0.82609576 | P21: =Q8 -> 0.81653984 | Q21: =S8 -> 0.0095559262 | R21: =O11 -> 0.76154837 | S21: =Q11 -> 1.1702952
A22: 1 | B22: 256 | C22: 0.0018 | D22: 1000 | E22: 224 | F22: 1 | G22: 0.89183063 | H22: 0.15410385 | I22: 0.56769013 | J22: =A22 & "_" & B22 & "_" & C22 & "_" & D22 & "_" & E22 -> 1_256_0.0018_1000_224 | K22: {=IF(F22=1, H22 - _xlfn.XLOOKUP(1, (J:J=J22)*(F:F=0), H:H), _xlfn.XLOOKUP(1, (J:J=J22)*(F:F=1), H:H) - H22 )} -> -0.0016990091 | L22: =IF(AND(F22=1, K22 > $N$2), 1, 0) -> 0 | M22: =IF(AND(F22=1, K22 < -$N$2), 1, 0) -> 0
A23: 1 | B23: 256 | C23: 0.0018 | D23: 1000 | E23: 224 | F23: 0 | G23: 0.88495073 | H23: 0.15580286 | I23: 0.53799195 | J23: =A23 & "_" & B23 & "_" & C23 & "_" & D23 & "_" & E23 -> 1_256_0.0018_1000_224 | K23: {=IF(F23=1, H23 - _xlfn.XLOOKUP(1, (J:J=J23)*(F:F=0), H:H), _xlfn.XLOOKUP(1, (J:J=J23)*(F:F=1), H:H) - H23 )} -> -0.0016990091 | L23: =IF(AND(F23=1, K23 > $N$2), 1, 0) -> 0 | M23: =IF(AND(F23=1, K23 < -$N$2), 1, 0) -> 0
A24: 1 | B24: 256 | C24: 0.002 | D24: 1000 | E24: 224 | F24: 1 | G24: 0.89943066 | H24: 0.16404887 | I24: 0.59064645 | J24: =A24 & "_" & B24 & "_" & C24 & "_" & D24 & "_" & E24 -> 1_256_0.002_1000_224 | K24: {=IF(F24=1, H24 - _xlfn.XLOOKUP(1, (J:J=J24)*(F:F=0), H:H), _xlfn.XLOOKUP(1, (J:J=J24)*(F:F=1), H:H) - H24 )} -> 0.014643093 | L24: =IF(AND(F24=1, K24 > $N$2), 1, 0) -> 1 | M24: =IF(AND(F24=1, K24 < -$N$2), 1, 0) -> 0
A25: 1 | B25: 256 | C25: 0.0025 | D25: 1000 | E25: 224 | F25: 1 | G25: 0.8861445 | H25: 0.1503268 | I25: 0.55485303 | J25: =A25 & "_" & B25 & "_" & C25 & "_" & D25 & "_" & E25 -> 1_256_0.0025_1000_224 | K25: {=IF(F25=1, H25 - _xlfn.XLOOKUP(1, (J:J=J25)*(F:F=0), H:H), _xlfn.XLOOKUP(1, (J:J=J25)*(F:F=1), H:H) - H25 )} -> 0.0066317827 | L25: =IF(AND(F25=1, K25 > $N$2), 1, 0) -> 1 | M25: =IF(AND(F25=1, K25 < -$N$2), 1, 0) -> 0
A26: 1 | B26: 256 | C26: 0.0025 | D26: 1000 | E26: 224 | F26: 0 | G26: 0.88450608 | H26: 0.14369501 | I26: 0.51475247 | J26: =A26 & "_" & B26 & "_" & C26 & "_" & D26 & "_" & E26 -> 1_256_0.0025_1000_224 | K26: {=IF(F26=1, H26 - _xlfn.XLOOKUP(1, (J:J=J26)*(F:F=0), H:H), _xlfn.XLOOKUP(1, (J:J=J26)*(F:F=1), H:H) - H26 )} -> 0.0066317827 | L26: =IF(AND(F26=1, K26 > $N$2), 1, 0) -> 0 | M26: =IF(AND(F26=1, K26 < -$N$2), 1, 0) -> 0 | O26: =O13 -> Average F1 with BFW | P26: =Q13 -> Average F1 without BFW | Q26: =S13 -> Difference in F1 mean with BFW - without BFW | R26: =O16 -> F1 Mean T Test p-value | S26: =Q16 -> Percent Improvement in AUC mean with BFW
A27: 1 | B27: 256 | C27: 0.002 | D27: 1000 | E27: 224 | F27: 0 | G27: 0.88875195 | H27: 0.14940577 | I27: 0.5630078 | J27: =A27 & "_" & B27 & "_" & C27 & "_" & D27 & "_" & E27 -> 1_256_0.002_1000_224 | K27: {=IF(F27=1, H27 - _xlfn.XLOOKUP(1, (J:J=J27)*(F:F=0), H:H), _xlfn.XLOOKUP(1, (J:J=J27)*(F:F=1), H:H) - H27 )} -> 0.014643093 | L27: =IF(AND(F27=1, K27 > $N$2), 1, 0) -> 0 | M27: =IF(AND(F27=1, K27 < -$N$2), 1, 0) -> 0 | O27: =O14 -> 0.11797939 | P27: =Q14 -> 0.111959 | Q27: =S14 -> 0.0060203876 | R27: =O17 -> 0.5907157 | S27: =Q17 -> 5.3773143
A28: 1 | B28: 512 | C28: 0.0005 | D28: 1000 | E28: 64 | F28: 1 | G28: 0.65311506 | H28: 0.041574525 | I28: 0.45470345 | J28: =A28 & "_" & B28 & "_" & C28 & "_" & D28 & "_" & E28 -> 1_512_0.0005_1000_64 | K28: {=IF(F28=1, H28 - _xlfn.XLOOKUP(1, (J:J=J28)*(F:F=0), H:H), _xlfn.XLOOKUP(1, (J:J=J28)*(F:F=1), H:H) - H28 )} -> -0.003401552 | L28: =IF(AND(F28=1, K28 > $N$2), 1, 0) -> 0 | M28: =IF(AND(F28=1, K28 < -$N$2), 1, 0) -> 1
A29: 1 | B29: 512 | C29: 0.0005 | D29: 1000 | E29: 64 | F29: 0 | G29: 0.65846859 | H29: 0.044976077 | I29: 0.47871372 | J29: =A29 & "_" & B29 & "_" & C29 & "_" & D29 & "_" & E29 -> 1_512_0.0005_1000_64 | K29: {=IF(F29=1, H29 - _xlfn.XLOOKUP(1, (J:J=J29)*(F:F=0), H:H), _xlfn.XLOOKUP(1, (J:J=J29)*(F:F=1), H:H) - H29 )} -> -0.003401552 | L29: =IF(AND(F29=1, K29 > $N$2), 1, 0) -> 0 | M29: =IF(AND(F29=1, K29 < -$N$2), 1, 0) -> 0
A30: 1 | B30: 512 | C30: 0.0005 | D30: 200 | E30: 64 | F30: 1 | G30: 0.66891426 | H30: 0.045090909 | I30: 0.50101401 | J30: =A30 & "_" & B30 & "_" & C30 & "_" & D30 & "_" & E30 -> 1_512_0.0005_200_64 | K30: {=IF(F30=1, H30 - _xlfn.XLOOKUP(1, (J:J=J30)*(F:F=0), H:H), _xlfn.XLOOKUP(1, (J:J=J30)*(F:F=1), H:H) - H30 )} -> 0.0010174533 | L30: =IF(AND(F30=1, K30 > $N$2), 1, 0) -> 0 | M30: =IF(AND(F30=1, K30 < -$N$2), 1, 0) -> 0
A31: 1 | B31: 512 | C31: 0.0005 | D31: 200 | E31: 64 | F31: 0 | G31: 0.66724672 | H31: 0.044073456 | I31: 0.40686054 | J31: =A31 & "_" & B31 & "_" & C31 & "_" & D31 & "_" & E31 -> 1_512_0.0005_200_64 | K31: {=IF(F31=1, H31 - _xlfn.XLOOKUP(1, (J:J=J31)*(F:F=0), H:H), _xlfn.XLOOKUP(1, (J:J=J31)*(F:F=1), H:H) - H31 )} -> 0.0010174533 | L31: =IF(AND(F31=1, K31 > $N$2), 1, 0) -> 0 | M31: =IF(AND(F31=1, K31 < -$N$2), 1, 0) -> 0
A32: 1 | B32: 512 | C32: 0.0005 | D32: 1000 | E32: 96 | F32: 1 | G32: 0.78422504 | H32: 0.064450128 | I32: 0.44371626 | J32: =A32 & "_" & B32 & "_" & C32 & "_" & D32 & "_" & E32 -> 1_512_0.0005_1000_96 | K32: {=IF(F32=1, H32 - _xlfn.XLOOKUP(1, (J:J=J32)*(F:F=0), H:H), _xlfn.XLOOKUP(1, (J:J=J32)*(F:F=1), H:H) - H32 )} -> 0.013758884 | L32: =IF(AND(F32=1, K32 > $N$2), 1, 0) -> 1 | M32: =IF(AND(F32=1, K32 < -$N$2), 1, 0) -> 0
A33: 1 | B33: 512 | C33: 0.0005 | D33: 1000 | E33: 96 | F33: 0 | G33: 0.73497681 | H33: 0.050691244 | I33: 0.46505102 | J33: =A33 & "_" & B33 & "_" & C33 & "_" & D33 & "_" & E33 -> 1_512_0.0005_1000_96 | K33: {=IF(F33=1, H33 - _xlfn.XLOOKUP(1, (J:J=J33)*(F:F=0), H:H), _xlfn.XLOOKUP(1, (J:J=J33)*(F:F=1), H:H) - H33 )} -> 0.013758884 | L33: =IF(AND(F33=1, K33 > $N$2), 1, 0) -> 0 | M33: =IF(AND(F33=1, K33 < -$N$2), 1, 0) -> 0
A34: 1 | B34: 512 | C34: 0.0005 | D34: 1000 | E34: 128 | F34: 1 | G34: 0.85442475 | H34: 0.09152752 | I34: 0.47731008 | J34: =A34 & "_" & B34 & "_" & C34 & "_" & D34 & "_" & E34 -> 1_512_0.0005_1000_128 | K34: {=IF(F34=1, H34 - _xlfn.XLOOKUP(1, (J:J=J34)*(F:F=0), H:H), _xlfn.XLOOKUP(1, (J:J=J34)*(F:F=1), H:H) - H34 )} -> 0.014171683 | L34: =IF(AND(F34=1, K34 > $N$2), 1, 0) -> 1 | M34: =IF(AND(F34=1, K34 < -$N$2), 1, 0) -> 0
A35: 1 | B35: 512 | C35: 0.0005 | D35: 1000 | E35: 128 | F35: 0 | G35: 0.82670043 | H35: 0.077355837 | I35: 0.44313676 | J35: =A35 & "_" & B35 & "_" & C35 & "_" & D35 & "_" & E35 -> 1_512_0.0005_1000_128 | K35: {=IF(F35=1, H35 - _xlfn.XLOOKUP(1, (J:J=J35)*(F:F=0), H:H), _xlfn.XLOOKUP(1, (J:J=J35)*(F:F=1), H:H) - H35 )} -> 0.014171683 | L35: =IF(AND(F35=1, K35 > $N$2), 1, 0) -> 0 | M35: =IF(AND(F35=1, K35 < -$N$2), 1, 0) -> 0
A36: 1 | B36: 512 | C36: 0.0005 | D36: 200 | E36: 128 | F36: 1 | G36: 0.81430369 | H36: 0.07793765 | I36: 0.50462532 | J36: =A36 & "_" & B36 & "_" & C36 & "_" & D36 & "_" & E36 -> 1_512_0.0005_200_128 | K36: {=IF(F36=1, H36 - _xlfn.XLOOKUP(1, (J:J=J36)*(F:F=0), H:H), _xlfn.XLOOKUP(1, (J:J=J36)*(F:F=1), H:H) - H36 )} -> -0.0016217136 | L36: =IF(AND(F36=1, K36 > $N$2), 1, 0) -> 0 | M36: =IF(AND(F36=1, K36 < -$N$2), 1, 0) -> 0
A37: 1 | B37: 512 | C37: 0.0005 | D37: 200 | E37: 128 | F37: 0 | G37: 0.83107375 | H37: 0.079559364 | I37: 0.42672834 | J37: =A37 & "_" & B37 & "_" & C37 & "_" & D37 & "_" & E37 -> 1_512_0.0005_200_128 | K37: {=IF(F37=1, H37 - _xlfn.XLOOKUP(1, (J:J=J37)*(F:F=0), H:H), _xlfn.XLOOKUP(1, (J:J=J37)*(F:F=1), H:H) - H37 )} -> -0.0016217136 | L37: =IF(AND(F37=1, K37 > $N$2), 1, 0) -> 0 | M37: =IF(AND(F37=1, K37 < -$N$2), 1, 0) -> 0
A38: 1 | B38: 512 | C38: 0.0005 | D38: 1000 | E38: 160 | F38: 1 | G38: 0.87066182 | H38: 0.10218978 | I38: 0.5199841 | J38: =A38 & "_" & B38 & "_" & C38 & "_" & D38 & "_" & E38 -> 1_512_0.0005_1000_160 | K38: {=IF(F38=1, H38 - _xlfn.XLOOKUP(1, (J:J=J38)*(F:F=0), H:H), _xlfn.XLOOKUP(1, (J:J=J38)*(F:F=1), H:H) - H38 )} -> 0.0024874001 | L38: =IF(AND(F38=1, K38 > $N$2), 1, 0) -> 1 | M38: =IF(AND(F38=1, K38 < -$N$2), 1, 0) -> 0
A39: 1 | B39: 512 | C39: 0.0005 | D39: 1000 | E39: 160 | F39: 0 | G39: 0.86373611 | H39: 0.099702381 | I39: 0.4272696 | J39: =A39 & "_" & B39 & "_" & C39 & "_" & D39 & "_" & E39 -> 1_512_0.0005_1000_160 | K39: {=IF(F39=1, H39 - _xlfn.XLOOKUP(1, (J:J=J39)*(F:F=0), H:H), _xlfn.XLOOKUP(1, (J:J=J39)*(F:F=1), H:H) - H39 )} -> 0.0024874001 | L39: =IF(AND(F39=1, K39 > $N$2), 1, 0) -> 0 | M39: =IF(AND(F39=1, K39 < -$N$2), 1, 0) -> 0
... A69: 1 | B69: 512 | C69: 0.0005 | D69: 200 | E69: 32 | F69: 0 | G69: 0.55199164 | H69: 0.028485346 | I69: 0.36821307 | J69: =A69 & "_" & B69 & "_" & C69 & "_" & D69 & "_" & E69 -> 1_512_0.0005_200_32 | K69: {=IF(F69=1, H69 - _xlfn.XLOOKUP(1, (J:J=J69)*(F:F=0), H:H), _xlfn.XLOOKUP(1, (J:J=J69)*(F:F=1), H:H) - H69 )} -> 0.0023431699 | L69: =IF(AND(F69=1, K69 > $N$2), 1, 0) -> 0 | M69: =IF(AND(F69=1, K69 < -$N$2), 1, 0) -> 0
...

Sheet dos
A1: feature extraction | B1: batch size | C1: learning rate | D1: epochs | E1: msg per input | F1: bfw | G1: auc | H1: max f1 | I1: max f1 threshhold | J1: config ID | K1: Tie Threshold | L1: Wins | M1: Loss | O1: Best AUC
A2: 1 | B2: 1024 | C2: 0.0018 | D2: 1000 | E2: 192 | F2: 1 | G2: 0.85436893 | H2: 0.90142672 | I2: 0.4522119 | J2: =A2 & "_" & B2 & "_" & C2 & "_" & D2 & "_" & E2 -> 1_1024_0.0018_1000_192 | K2: {=IF(F2=1, H2 - _xlfn.XLOOKUP(1, (J:J=J2)*(F:F=0), H:H), _xlfn.XLOOKUP(1, (J:J=J2)*(F:F=1), H:H) - H2 )} -> -0.00078970909 | L2: =IF(AND(F2=1, K2 > $N$2), 1, 0) -> 0 | M2: =IF(AND(F2=1, K2 < -$N$2), 1, 0) -> 0 | N2: 0.002 | O2: feature extraction | P2: batch size | Q2: learning rate | R2: epochs | S2: msg per input | T2: bfw | U2: auc | V2: max f1 | W2: max f1 threshhold | X2: config ID | Y2: Tie Threshold
A3: 1 | B3: 1024 | C3: 0.0018 | D3: 1000 | E3: 192 | F3: 1 | G3: 0.85451266 | H3: 0.89967638 | I3: 0.45170945 | J3: =A3 & "_" & B3 & "_" & C3 & "_" & D3 & "_" & E3 -> 1_1024_0.0018_1000_192 | K3: {=IF(F3=1, H3 - _xlfn.XLOOKUP(1, (J:J=J3)*(F:F=0), H:H), _xlfn.XLOOKUP(1, (J:J=J3)*(F:F=1), H:H) - H3 )} -> -0.0025400522 | L3: =IF(AND(F3=1, K3 > $N$2), 1, 0) -> 0 | M3: =IF(AND(F3=1, K3 < -$N$2), 1, 0) -> 1 | O3: {=_xlfn.XLOOKUP(MAX(G:G), G:G, A:A:K:K)} -> 1 | P3: 512 | Q3: 0.0001 | R3: 1000 | S3: 256 | T3: 0 | U3: 0.87194574 | V3: 0.91052632 | W3: 0.47789695 | X3: 1_512_0.0001_1000_256 | Y3: -0.037359793
A4: 1 | B4: 1024 | C4: 0.0018 | D4: 1000 | E4: 192 | F4: 1 | G4: 0.85461466 | H4: 0.90142672 | I4: 0.45219131 | J4: =A4 & "_" & B4 & "_" & C4 & "_" & D4 & "_" & E4 -> 1_1024_0.0018_1000_192 | K4: {=IF(F4=1, H4 - _xlfn.XLOOKUP(1, (J:J=J4)*(F:F=0), H:H), _xlfn.XLOOKUP(1, (J:J=J4)*(F:F=1), H:H) - H4 )} -> -0.00078970909 | L4: =IF(AND(F4=1, K4 > $N$2), 1, 0) -> 0 | M4: =IF(AND(F4=1, K4 < -$N$2), 1, 0) -> 0 | O4: Best F1
A5: 1 | B5: 1024 | C5: 0.0018 | D5: 1000 | E5: 192 | F5: 0 | G5: 0.85139465 | H5: 0.90221643 | I5: 0.42869146 | J5: =A5 & "_" & B5 & "_" & C5 & "_" & D5 & "_" & E5 -> 1_1024_0.0018_1000_192 | K5: {=IF(F5=1, H5 - _xlfn.XLOOKUP(1, (J:J=J5)*(F:F=0), H:H), _xlfn.XLOOKUP(1, (J:J=J5)*(F:F=1), H:H) - H5 )} -> -0.00078970909 | L5: =IF(AND(F5=1, K5 > $N$2), 1, 0) -> 0 | M5: =IF(AND(F5=1, K5 < -$N$2), 1, 0) -> 0 | O5: {=_xlfn.XLOOKUP(MAX(H:H), H:H, A:A:K:K)} -> 1 | P5: 256 | Q5: 0.0018 | R5: 1000 | S5: 224 | T5: 0 | U5: 0.85944816 | V5: 0.91271057 | W5: 0.45090365 | X5: 1_256_0.0018_1000_224 | Y5: -0.0001338795
A6: 1 | B6: 1024 | C6: 0.002 | D6: 1000 | E6: 192 | F6: 1 | G6: 0.84939054 | H6: 0.90201168 | I6: 0.46174795 | J6: =A6 & "_" & B6 & "_" & C6 & "_" & D6 & "_" & E6 -> 1_1024_0.002_1000_192 | K6: {=IF(F6=1, H6 - _xlfn.XLOOKUP(1, (J:J=J6)*(F:F=0), H:H), _xlfn.XLOOKUP(1, (J:J=J6)*(F:F=1), H:H) - H6 )} -> -0.003278979 | L6: =IF(AND(F6=1, K6 > $N$2), 1, 0) -> 0 | M6: =IF(AND(F6=1, K6 < -$N$2), 1, 0) -> 1
A7: 1 | B7: 1024 | C7: 0.0025 | D7: 1000 | E7: 192 | F7: 1 | G7: 0.85353205 | H7: 0.90355987 | I7: 0.4459174 | J7: =A7 & "_" & B7 & "_" & C7 & "_" & D7 & "_" & E7 -> 1_1024_0.0025_1000_192 | K7: {=IF(F7=1, H7 - _xlfn.XLOOKUP(1, (J:J=J7)*(F:F=0), H:H), _xlfn.XLOOKUP(1, (J:J=J7)*(F:F=1), H:H) - H7 )} -> 0.0018781112 | L7: =IF(AND(F7=1, K7 > $N$2), 1, 0) -> 0 | M7: =IF(AND(F7=1, K7 < -$N$2), 1, 0) -> 0 | O7: Average AUC with BFW | Q7: Average AUC without BFW | S7: Difference in AUC mean with BFW - without BFW
A8: 1 | B8: 1024 | C8: 0.0025 | D8: 1000 | E8: 192 | F8: 0 | G8: 0.85097621 | H8: 0.90168176 | I8: 0.42360062 | J8: =A8 & "_" & B8 & "_" & C8 & "_" & D8 & "_" & E8 -> 1_1024_0.0025_1000_192 | K8: {=IF(F8=1, H8 - _xlfn.XLOOKUP(1, (J:J=J8)*(F:F=0), H:H), _xlfn.XLOOKUP(1, (J:J=J8)*(F:F=1), H:H) - H8 )} -> 0.0018781112 | L8: =IF(AND(F8=1, K8 > $N$2), 1, 0) -> 0 | M8: =IF(AND(F8=1, K8 < -$N$2), 1, 0) -> 0 | O8: =AVERAGEIF(F:F, 1, G:G) -> 0.80550158 | Q8: =AVERAGEIF(F:F, 0, G:G) -> 0.81437112 | S8: =O8-Q8 -> -0.0088695417
A9: 1 | B9: 1024 | C9: 0.002 | D9: 1000 | E9: 192 | F9: 0 | G9: 0.85421593 | H9: 0.90529066 | I9: 0.44673848 | J9: =A9 & "_" & B9 & "_" & C9 & "_" & D9 & "_" & E9 -> 1_1024_0.002_1000_192 | K9: {=IF(F9=1, H9 - _xlfn.XLOOKUP(1, (J:J=J9)*(F:F=0), H:H), _xlfn.XLOOKUP(1, (J:J=J9)*(F:F=1), H:H) - H9 )} -> -0.003278979 | L9: =IF(AND(F9=1, K9 > $N$2), 1, 0) -> 0 | M9: =IF(AND(F9=1, K9 < -$N$2), 1, 0) -> 0
A10: 1 | B10: 1024 | C10: 0.0018 | D10: 1000 | E10: 224 | F10: 1 | G10: 0.84687165 | H10: 0.90288316 | I10: 0.46586354 | J10: =A10 & "_" & B10 & "_" & C10 & "_" & D10 & "_" & E10 -> 1_1024_0.0018_1000_224 | K10: {=IF(F10=1, H10 - _xlfn.XLOOKUP(1, (J:J=J10)*(F:F=0), H:H), _xlfn.XLOOKUP(1, (J:J=J10)*(F:F=1), H:H) - H10 )} -> -0.0028919197 | L10: =IF(AND(F10=1, K10 > $N$2), 1, 0) -> 0 | M10: =IF(AND(F10=1, K10 < -$N$2), 1, 0) -> 1 | O10: AUC Mean T Test p-value | Q10: Percent Improvement in AUC mean with BFW
A11: 1 | B11: 1024 | C11: 0.0018 | D11: 1000 | E11: 224 | F11: 0 | G11: 0.85359058 | H11: 0.90577508 | I11: 0.43965079 | J11: =A11 & "_" & B11 & "_" & C11 & "_" & D11 & "_" & E11 -> 1_1024_0.0018_1000_224 | K11: {=IF(F11=1, H11 - _xlfn.XLOOKUP(1, (J:J=J11)*(F:F=0), H:H), _xlfn.XLOOKUP(1, (J:J=J11)*(F:F=1), H:H) - H11 )} -> -0.0028919197 | L11: =IF(AND(F11=1, K11 > $N$2), 1, 0) -> 0 | M11: =IF(AND(F11=1, K11 < -$N$2), 1, 0) -> 0 | O11: {=_xlfn.T.TEST(_xlfn._xlws.FILTER(G:G, F:F=1), _xlfn._xlws.FILTER(G:G, F:F=0), 2, 3)} -> 0.71461429 | Q11: =(S8)/Q8*100 -> -1.0891277
A12: 1 | B12: 1024 | C12: 0.002 | D12: 1000 | E12: 224 | F12: 1 | G12: 0.8573973 | H12: 0.9070122 | I12: 0.45825681 | J12: =A12 & "_" & B12 & "_" & C12 & "_" & D12 & "_" & E12 -> 1_1024_0.002_1000_224 | K12: {=IF(F12=1, H12 - _xlfn.XLOOKUP(1, (J:J=J12)*(F:F=0), H:H), _xlfn.XLOOKUP(1, (J:J=J12)*(F:F=1), H:H) - H12 )} -> -0.0016600996 | L12: =IF(AND(F12=1, K12 > $N$2), 1, 0) -> 0 | M12: =IF(AND(F12=1, K12 < -$N$2), 1, 0) -> 0
A13: 1 | B13: 1024 | C13: 0.0025 | D13: 1000 | E13: 224 | F13: 1 | G13: 0.85991039 | H13: 0.91089109 | I13: 0.45444441 | J13: =A13 & "_" & B13 & "_" & C13 & "_" & D13 & "_" & E13 -> 1_1024_0.0025_1000_224 | K13: {=IF(F13=1, H13 - _xlfn.XLOOKUP(1, (J:J=J13)*(F:F=0), H:H), _xlfn.XLOOKUP(1, (J:J=J13)*(F:F=1), H:H) - H13 )} -> 0.003878894 | L13: =IF(AND(F13=1, K13 > $N$2), 1, 0) -> 1 | M13: =IF(AND(F13=1, K13 < -$N$2), 1, 0) -> 0 | O13: Average F1 with BFW | Q13: Average F1 without BFW | S13: Difference in F1 mean with BFW - without BFW
A14: 1 | B14: 1024 | C14: 0.0025 | D14: 1000 | E14: 224 | F14: 0 | G14: 0.8557077 | H14: 0.9070122 | I14: 0.44505274 | J14: =A14 & "_" & B14 & "_" & C14 & "_" & D14 & "_" & E14 -> 1_1024_0.0025_1000_224 | K14: {=IF(F14=1, H14 - _xlfn.XLOOKUP(1, (J:J=J14)*(F:F=0), H:H), _xlfn.XLOOKUP(1, (J:J=J14)*(F:F=1), H:H) - H14 )} -> 0.003878894 | L14: =IF(AND(F14=1, K14 > $N$2), 1, 0) -> 0 | M14: =IF(AND(F14=1, K14 < -$N$2), 1, 0) -> 0 | O14: =AVERAGEIF(F:F, 1, H:H) -> 0.86421745 | Q14: =AVERAGEIF(F:F, 0, H:H) -> 0.87296777 | S14: =O14-Q14 -> -0.0087503198
A15: 1 | B15: 1024 | C15: 0.002 | D15: 1000 | E15: 224 | F15: 0 | G15: 0.86054458 | H15: 0.90867229 | I15: 0.457027 | J15: =A15 & "_" & B15 & "_" & C15 & "_" & D15 & "_" & E15 -> 1_1024_0.002_1000_224 | K15: {=IF(F15=1, H15 - _xlfn.XLOOKUP(1, (J:J=J15)*(F:F=0), H:H), _xlfn.XLOOKUP(1, (J:J=J15)*(F:F=1), H:H) - H15 )} -> -0.0016600996 | L15: =IF(AND(F15=1, K15 > $N$2), 1, 0) -> 0 | M15: =IF(AND(F15=1, K15 < -$N$2), 1, 0) -> 0
A16: 1 | B16: 256 | C16: 0.0018 | D16: 1000 | E16: 192 | F16: 1 | G16: 0.84741077 | H16: 0.89490651 | I16: 0.42942099 | J16: =A16 & "_" & B16 & "_" & C16 & "_" & D16 & "_" & E16 -> 1_256_0.0018_1000_192 | K16: {=IF(F16=1, H16 - _xlfn.XLOOKUP(1, (J:J=J16)*(F:F=0), H:H), _xlfn.XLOOKUP(1, (J:J=J16)*(F:F=1), H:H) - H16 )} -> -0.010288293 | L16: =IF(AND(F16=1, K16 > $N$2), 1, 0) -> 0 | M16: =IF(AND(F16=1, K16 < -$N$2), 1, 0) -> 1 | O16: F1 Mean T Test p-value | Q16: Percent Improvement in AUC mean with BFW
A17: 1 | B17: 256 | C17: 0.0018 | D17: 1000 | E17: 192 | F17: 0 | G17: 0.84816651 | H17: 0.90519481 | I17: 0.42610096 | J17: =A17 & "_" & B17 & "_" & C17 & "_" & D17 & "_" & E17 -> 1_256_0.0018_1000_192 | K17: {=IF(F17=1, H17 - _xlfn.XLOOKUP(1, (J:J=J17)*(F:F=0), H:H), _xlfn.XLOOKUP(1, (J:J=J17)*(F:F=1), H:H) - H17 )} -> -0.010288293 | L17: =IF(AND(F17=1, K17 > $N$2), 1, 0) -> 0 | M17: =IF(AND(F17=1, K17 < -$N$2), 1, 0) -> 0 | O17: {=_xlfn.T.TEST(_xlfn._xlws.FILTER(H:H, F:F=1), _xlfn._xlws.FILTER(H:H, F:F=0), 2, 3)} -> 0.59145095 | Q17: =(S14)/Q14*100 -> -1.0023646
A18: 1 | B18: 256 | C18: 0.002 | D18: 1000 | E18: 192 | F18: 1 | G18: 0.84893848 | H18: 0.89877498 | I18: 0.42985877 | J18: =A18 & "_" & B18 & "_" & C18 & "_" & D18 & "_" & E18 -> 1_256_0.002_1000_192 | K18: {=IF(F18=1, H18 - _xlfn.XLOOKUP(1, (J:J=J18)*(F:F=0), H:H), _xlfn.XLOOKUP(1, (J:J=J18)*(F:F=1), H:H) - H18 )} -> -0.0061729328 | L18: =IF(AND(F18=1, K18 > $N$2), 1, 0) -> 0 | M18: =IF(AND(F18=1, K18 < -$N$2), 1, 0) -> 1
A19: 1 | B19: 256 | C19: 0.0025 | D19: 1000 | E19: 192 | F19: 1 | G19: 0.85225123 | H19: 0.90142672 | I19: 0.43281056 | J19: =A19 & "_" & B19 & "_" & C19 & "_" & D19 & "_" & E19 -> 1_256_0.0025_1000_192 | K19: {=IF(F19=1, H19 - _xlfn.XLOOKUP(1, (J:J=J19)*(F:F=0), H:H), _xlfn.XLOOKUP(1, (J:J=J19)*(F:F=1), H:H) - H19 )} -> -0.0030235432 | L19: =IF(AND(F19=1, K19 > $N$2), 1, 0) -> 0 | M19: =IF(AND(F19=1, K19 < -$N$2), 1, 0) -> 1
A20: 1 | B20: 256 | C20: 0.0025 | D20: 1000 | E20: 192 | F20: 0 | G20: 0.84810856 | H20: 0.90445026 | I20: 0.44034464 | J20: =A20 & "_" & B20 & "_" & C20 & "_" & D20 & "_" & E20 -> 1_256_0.0025_1000_192 | K20: {=IF(F20=1, H20 - _xlfn.XLOOKUP(1, (J:J=J20)*(F:F=0), H:H), _xlfn.XLOOKUP(1, (J:J=J20)*(F:F=1), H:H) - H20 )} -> -0.0030235432 | L20: =IF(AND(F20=1, K20 > $N$2), 1, 0) -> 0 | M20: =IF(AND(F20=1, K20 < -$N$2), 1, 0) -> 0 | O20: =O7 -> Average AUC with BFW | P20: =Q7 -> Average AUC without BFW | Q20: =S7 -> Difference in AUC mean with BFW - without BFW | R20: =O10 -> AUC Mean T Test p-value | S20: =Q10 -> Percent Improvement in AUC mean with BFW
A21: 1 | B21: 256 | C21: 0.002 | D21: 1000 | E21: 192 | F21: 0 | G21: 0.84958179 | H21: 0.90494792 | I21: 0.43117815 | J21: =A21 & "_" & B21 & "_" & C21 & "_" & D21 & "_" & E21 -> 1_256_0.002_1000_192 | K21: {=IF(F21=1, H21 - _xlfn.XLOOKUP(1, (J:J=J21)*(F:F=0), H:H), _xlfn.XLOOKUP(1, (J:J=J21)*(F:F=1), H:H) - H21 )} -> -0.0061729328 | L21: =IF(AND(F21=1, K21 > $N$2), 1, 0) -> 0 | M21: =IF(AND(F21=1, K21 < -$N$2), 1, 0) -> 0 | O21: =O8 -> 0.80550158 | P21: =Q8 -> 0.81437112 | Q21: =S8 -> -0.0088695417 | R21: =O11 -> 0.71461429 | S21: =Q11 -> -1.0891277
A22: 1 | B22: 256 | C22: 0.0018 | D22: 1000 | E22: 224 | F22: 1 | G22: 0.86186187 | H22: 0.91257669 | I22: 0.45223449 | J22: =A22 & "_" & B22 & "_" & C22 & "_" & D22 & "_" & E22 -> 1_256_0.0018_1000_224 | K22: {=IF(F22=1, H22 - _xlfn.XLOOKUP(1, (J:J=J22)*(F:F=0), H:H), _xlfn.XLOOKUP(1, (J:J=J22)*(F:F=1), H:H) - H22 )} -> -0.0001338795 | L22: =IF(AND(F22=1, K22 > $N$2), 1, 0) -> 0 | M22: =IF(AND(F22=1, K22 < -$N$2), 1, 0) -> 0
A23: 1 | B23: 256 | C23: 0.0018 | D23: 1000 | E23: 224 | F23: 0 | G23: 0.85944816 | H23: 0.91271057 | I23: 0.45090365 | J23: =A23 & "_" & B23 & "_" & C23 & "_" & D23 & "_" & E23 -> 1_256_0.0018_1000_224 | K23: {=IF(F23=1, H23 - _xlfn.XLOOKUP(1, (J:J=J23)*(F:F=0), H:H), _xlfn.XLOOKUP(1, (J:J=J23)*(F:F=1), H:H) - H23 )} -> -0.0001338795 | L23: =IF(AND(F23=1, K23 > $N$2), 1, 0) -> 0 | M23: =IF(AND(F23=1, K23 < -$N$2), 1, 0) -> 0
A24: 1 | B24: 256 | C24: 0.002 | D24: 1000 | E24: 224 | F24: 1 | G24: 0.86048621 | H24: 0.91160646 | I24: 0.4630427 | J24: =A24 & "_" & B24 & "_" & C24 & "_" & D24 & "_" & E24 -> 1_256_0.002_1000_224 | K24: {=IF(F24=1, H24 - _xlfn.XLOOKUP(1, (J:J=J24)*(F:F=0), H:H), _xlfn.XLOOKUP(1, (J:J=J24)*(F:F=1), H:H) - H24 )} -> 0.0051647388 | L24: =IF(AND(F24=1, K24 > $N$2), 1, 0) -> 1 | M24: =IF(AND(F24=1, K24 < -$N$2), 1, 0) -> 0
A25: 1 | B25: 256 | C25: 0.0025 | D25: 1000 | E25: 224 | F25: 1 | G25: 0.85349277 | H25: 0.90362375 | I25: 0.46472752 | J25: =A25 & "_" & B25 & "_" & C25 & "_" & D25 & "_" & E25 -> 1_256_0.0025_1000_224 | K25: {=IF(F25=1, H25 - _xlfn.XLOOKUP(1, (J:J=J25)*(F:F=0), H:H), _xlfn.XLOOKUP(1, (J:J=J25)*(F:F=1), H:H) - H25 )} -> -0.0036559464 | L25: =IF(AND(F25=1, K25 > $N$2), 1, 0) -> 0 | M25: =IF(AND(F25=1, K25 < -$N$2), 1, 0) -> 1
A26: 1 | B26: 256 | C26: 0.0025 | D26: 1000 | E26: 224 | F26: 0 | G26: 0.8544204 | H26: 0.90727969 | I26: 0.45185108 | J26: =A26 & "_" & B26 & "_" & C26 & "_" & D26 & "_" & E26 -> 1_256_0.0025_1000_224 | K26: {=IF(F26=1, H26 - _xlfn.XLOOKUP(1, (J:J=J26)*(F:F=0), H:H), _xlfn.XLOOKUP(1, (J:J=J26)*(F:F=1), H:H) - H26 )} -> -0.0036559464 | L26: =IF(AND(F26=1, K26 > $N$2), 1, 0) -> 0 | M26: =IF(AND(F26=1, K26 < -$N$2), 1, 0) -> 0 | O26: =O13 -> Average F1 with BFW | P26: =Q13 -> Average F1 without BFW | Q26: =S13 -> Difference in F1 mean with BFW - without BFW | R26: =O16 -> F1 Mean T Test p-value | S26: =Q16 -> Percent Improvement in AUC mean with BFW
A27: 1 | B27: 256 | C27: 0.002 | D27: 1000 | E27: 224 | F27: 0 | G27: 0.85473591 | H27: 0.90644172 | I27: 0.45541424 | J27: =A27 & "_" & B27 & "_" & C27 & "_" & D27 & "_" & E27 -> 1_256_0.002_1000_224 | K27: {=IF(F27=1, H27 - _xlfn.XLOOKUP(1, (J:J=J27)*(F:F=0), H:H), _xlfn.XLOOKUP(1, (J:J=J27)*(F:F=1), H:H) - H27 )} -> 0.0051647388 | L27: =IF(AND(F27=1, K27 > $N$2), 1, 0) -> 0 | M27: =IF(AND(F27=1, K27 < -$N$2), 1, 0) -> 0 | O27: =O14 -> 0.86421745 | P27: =Q14 -> 0.87296777 | Q27: =S14 -> -0.0087503198 | R27: =O17 -> 0.59145095 | S27: =Q17 -> -1.0023646
A28: 1 | B28: 512 | C28: 0.0005 | D28: 1000 | E28: 64 | F28: 1 | G28: 0.76307011 | H28: 0.79379598 | I28: 0.31407885 | J28: =A28 & "_" & B28 & "_" & C28 & "_" & D28 & "_" & E28 -> 1_512_0.0005_1000_64 | K28: {=IF(F28=1, H28 - _xlfn.XLOOKUP(1, (J:J=J28)*(F:F=0), H:H), _xlfn.XLOOKUP(1, (J:J=J28)*(F:F=1), H:H) - H28 )} -> -0.020971681 | L28: =IF(AND(F28=1, K28 > $N$2), 1, 0) -> 0 | M28: =IF(AND(F28=1, K28 < -$N$2), 1, 0) -> 1
A29: 1 | B29: 512 | C29: 0.0005 | D29: 1000 | E29: 64 | F29: 0 | G29: 0.78064386 | H29: 0.81476766 | I29: 0.33266849 | J29: =A29 & "_" & B29 & "_" & C29 & "_" & D29 & "_" & E29 -> 1_512_0.0005_1000_64 | K29: {=IF(F29=1, H29 - _xlfn.XLOOKUP(1, (J:J=J29)*(F:F=0), H:H), _xlfn.XLOOKUP(1, (J:J=J29)*(F:F=1), H:H) - H29 )} -> -0.020971681 | L29: =IF(AND(F29=1, K29 > $N$2), 1, 0) -> 0 | M29: =IF(AND(F29=1, K29 < -$N$2), 1, 0) -> 0
A30: 1 | B30: 512 | C30: 0.0005 | D30: 200 | E30: 64 | F30: 1 | G30: 0.75769738 | H30: 0.7936576 | I30: 0.39956305 | J30: =A30 & "_" & B30 & "_" & C30 & "_" & D30 & "_" & E30 -> 1_512_0.0005_200_64 | K30: {=IF(F30=1, H30 - _xlfn.XLOOKUP(1, (J:J=J30)*(F:F=0), H:H), _xlfn.XLOOKUP(1, (J:J=J30)*(F:F=1), H:H) - H30 )} -> -0.017444641 | L30: =IF(AND(F30=1, K30 > $N$2), 1, 0) -> 0 | M30: =IF(AND(F30=1, K30 < -$N$2), 1, 0) -> 1
A31: 1 | B31: 512 | C31: 0.0005 | D31: 200 | E31: 64 | F31: 0 | G31: 0.78691145 | H31: 0.81110224 | I31: 0.31494709 | J31: =A31 & "_" & B31 & "_" & C31 & "_" & D31 & "_" & E31 -> 1_512_0.0005_200_64 | K31: {=IF(F31=1, H31 - _xlfn.XLOOKUP(1, (J:J=J31)*(F:F=0), H:H), _xlfn.XLOOKUP(1, (J:J=J31)*(F:F=1), H:H) - H31 )} -> -0.017444641 | L31: =IF(AND(F31=1, K31 > $N$2), 1, 0) -> 0 | M31: =IF(AND(F31=1, K31 < -$N$2), 1, 0) -> 0
A32: 1 | B32: 512 | C32: 0.0005 | D32: 1000 | E32: 96 | F32: 1 | G32: 0.81374394 | H32: 0.84712396 | I32: 0.36834645 | J32: =A32 & "_" & B32 & "_" & C32 & "_" & D32 & "_" & E32 -> 1_512_0.0005_1000_96 | K32: {=IF(F32=1, H32 - _xlfn.XLOOKUP(1, (J:J=J32)*(F:F=0), H:H), _xlfn.XLOOKUP(1, (J:J=J32)*(F:F=1), H:H) - H32 )} -> -0.017243854 | L32: =IF(AND(F32=1, K32 > $N$2), 1, 0) -> 0 | M32: =IF(AND(F32=1, K32 < -$N$2), 1, 0) -> 1
A33: 1 | B33: 512 | C33: 0.0005 | D33: 1000 | E33: 96 | F33: 0 | G33: 0.83497386 | H33: 0.86436782 | I33: 0.37838875 | J33: =A33 & "_" & B33 & "_" & C33 & "_" & D33 & "_" & E33 -> 1_512_0.0005_1000_96 | K33: {=IF(F33=1, H33 - _xlfn.XLOOKUP(1, (J:J=J33)*(F:F=0), H:H), _xlfn.XLOOKUP(1, (J:J=J33)*(F:F=1), H:H) - H33 )} -> -0.017243854 | L33: =IF(AND(F33=1, K33 > $N$2), 1, 0) -> 0 | M33: =IF(AND(F33=1, K33 < -$N$2), 1, 0) -> 0
A34: 1 | B34: 512 | C34: 0.0005 | D34: 1000 | E34: 128 | F34: 1 | G34: 0.82898485 | H34: 0.86382623 | I34: 0.44550064 | J34: =A34 & "_" & B34 & "_" & C34 & "_" & D34 & "_" & E34 -> 1_512_0.0005_1000_128 | K34: {=IF(F34=1, H34 - _xlfn.XLOOKUP(1, (J:J=J34)*(F:F=0), H:H), _xlfn.XLOOKUP(1, (J:J=J34)*(F:F=1), H:H) - H34 )} -> -0.0065999408 | L34: =IF(AND(F34=1, K34 > $N$2), 1, 0) -> 0 | M34: =IF(AND(F34=1, K34 < -$N$2), 1, 0) -> 1
A35: 1 | B35: 512 | C35: 0.0005 | D35: 1000 | E35: 128 | F35: 0 | G35: 0.82502377 | H35: 0.87042617 | I35: 0.39110203 | J35: =A35 & "_" & B35 & "_" & C35 & "_" & D35 & "_" & E35 -> 1_512_0.0005_1000_128 | K35: {=IF(F35=1, H35 - _xlfn.XLOOKUP(1, (J:J=J35)*(F:F=0), H:H), _xlfn.XLOOKUP(1, (J:J=J35)*(F:F=1), H:H) - H35 )} -> -0.0065999408 | L35: =IF(AND(F35=1, K35 > $N$2), 1, 0) -> 0 | M35: =IF(AND(F35=1, K35 < -$N$2), 1, 0) -> 0
A36: 1 | B36: 512 | C36: 0.0005 | D36: 200 | E36: 128 | F36: 1 | G36: 0.80163286 | H36: 0.84938272 | I36: 0.43834545 | J36: =A36 & "_" & B36 & "_" & C36 & "_" & D36 & "_" & E36 -> 1_512_0.0005_200_128 | K36: {=IF(F36=1, H36 - _xlfn.XLOOKUP(1, (J:J=J36)*(F:F=0), H:H), _xlfn.XLOOKUP(1, (J:J=J36)*(F:F=1), H:H) - H36 )} -> -0.036270389 | L36: =IF(AND(F36=1, K36 > $N$2), 1, 0) -> 0 | M36: =IF(AND(F36=1, K36 < -$N$2), 1, 0) -> 1
A37: 1 | B37: 512 | C37: 0.0005 | D37: 200 | E37: 128 | F37: 0 | G37: 0.83539604 | H37: 0.8856531 | I37: 0.39235384 | J37: =A37 & "_" & B37 & "_" & C37 & "_" & D37 & "_" & E37 -> 1_512_0.0005_200_128 | K37: {=IF(F37=1, H37 - _xlfn.XLOOKUP(1, (J:J=J37)*(F:F=0), H:H), _xlfn.XLOOKUP(1, (J:J=J37)*(F:F=1), H:H) - H37 )} -> -0.036270389 | L37: =IF(AND(F37=1, K37 > $N$2), 1, 0) -> 0 | M37: =IF(AND(F37=1, K37 < -$N$2), 1, 0) -> 0
A38: 1 | B38: 512 | C38: 0.0005 | D38: 1000 | E38: 160 | F38: 1 | G38: 0.82676386 | H38: 0.88114105 | I38: 0.47731801 | J38: =A38 & "_" & B38 & "_" & C38 & "_" & D38 & "_" & E38 -> 1_512_0.0005_1000_160 | K38: {=IF(F38=1, H38 - _xlfn.XLOOKUP(1, (J:J=J38)*(F:F=0), H:H), _xlfn.XLOOKUP(1, (J:J=J38)*(F:F=1), H:H) - H38 )} -> -0.014076579 | L38: =IF(AND(F38=1, K38 > $N$2), 1, 0) -> 0 | M38: =IF(AND(F38=1, K38 < -$N$2), 1, 0) -> 1
A39: 1 | B39: 512 | C39: 0.0005 | D39: 1000 | E39: 160 | F39: 0 | G39: 0.84920393 | H39: 0.89521762 | I39: 0.40687051 | J39: =A39 & "_" & B39 & "_" & C39 & "_" & D39 & "_" & E39 -> 1_512_0.0005_1000_160 | K39: {=IF(F39=1, H39 - _xlfn.XLOOKUP(1, (J:J=J39)*(F:F=0), H:H), _xlfn.XLOOKUP(1, (J:J=J39)*(F:F=1), H:H) - H39 )} -> -0.014076579 | L39: =IF(AND(F39=1, K39 > $N$2), 1, 0) -> 0 | M39: =IF(AND(F39=1, K39 < -$N$2), 1, 0) -> 0
... A69: 1 | B69: 512 | C69: 0.0005 | D69: 200 | E69: 32 | F69: 0 | G69: 0.64848357 | H69: 0.71783722 | I69: 0.20994888 | J69: =A69 & "_" & B69 & "_" & C69 & "_" & D69 & "_" & E69 -> 1_512_0.0005_200_32 | K69: {=IF(F69=1, H69 - _xlfn.XLOOKUP(1, (J:J=J69)*(F:F=0), H:H), _xlfn.XLOOKUP(1, (J:J=J69)*(F:F=1), H:H) - H69 )} -> 0.0032064961 | L69: =IF(AND(F69=1, K69 > $N$2), 1, 0) -> 0 | M69: =IF(AND(F69=1, K69 < -$N$2), 1, 0) -> 0
...

Sheet fuzzy
A1: feature extraction | B1: batch size | C1: learning rate | D1: epochs | E1: msg per input | F1: bfw | G1: auc | H1: max f1 | I1: max f1 threshhold | J1: config ID | K1: Tie Threshold | L1: Wins | M1: Loss | O1: Best AUC
A2: 1 | B2: 1024 | C2: 0.0018 | D2: 1000 | E2: 192 | F2: 1 | G2: 0.99882667 | H2: 0.99494949 | I2: 0.84762159 | J2: =A2 & "_" & B2 & "_" & C2 & "_" & D2 & "_" & E2 -> 1_1024_0.0018_1000_192 | K2: {=IF(F2=1, H2 - _xlfn.XLOOKUP(1, (J:J=J2)*(F:F=0), H:H), _xlfn.XLOOKUP(1, (J:J=J2)*(F:F=1), H:H) - H2 )} -> -0.001010101 | L2: =IF(AND(F2=1, K2 > $N$2), 1, 0) -> 0 | M2: =IF(AND(F2=1, K2 < -$N$2), 1, 0) -> 0 | N2: 0.002 | O2: feature extraction | P2: batch size | Q2: learning rate | R2: epochs | S2: msg per input | T2: bfw | U2: auc | V2: max f1 | W2: max f1 threshhold | X2: config ID | Y2: Tie Threshold
A3: 1 | B3: 1024 | C3: 0.0018 | D3: 1000 | E3: 192 | F3: 1 | G3: 0.99882757 | H3: 0.99494949 | I3: 0.84790625 | J3: =A3 & "_" & B3 & "_" & C3 & "_" & D3 & "_" & E3 -> 1_1024_0.0018_1000_192 | K3: {=IF(F3=1, H3 - _xlfn.XLOOKUP(1, (J:J=J3)*(F:F=0), H:H), _xlfn.XLOOKUP(1, (J:J=J3)*(F:F=1), H:H) - H3 )} -> -0.001010101 | L3: =IF(AND(F3=1, K3 > $N$2), 1, 0) -> 0 | M3: =IF(AND(F3=1, K3 < -$N$2), 1, 0) -> 0 | O3: {=_xlfn.XLOOKUP(MAX(G:G), G:G, A:A:K:K)} -> 1 | P3: 512 | Q3: 0.0005 | R3: 1000 | S3: 128 | T3: 0 | U3: 0.99966169 | V3: 0.99088761 | W3: 0.82213952 | X3: 1_512_0.0005_1000_128 | Y3: -0.011502687
A4: 1 | B4: 1024 | C4: 0.0018 | D4: 1000 | E4: 192 | F4: 1 | G4: 0.99882656 | H4: 0.99494949 | I4: 0.84748888 | J4: =A4 & "_" & B4 & "_" & C4 & "_" & D4 & "_" & E4 -> 1_1024_0.0018_1000_192 | K4: {=IF(F4=1, H4 - _xlfn.XLOOKUP(1, (J:J=J4)*(F:F=0), H:H), _xlfn.XLOOKUP(1, (J:J=J4)*(F:F=1), H:H) - H4 )} -> -0.001010101 | L4: =IF(AND(F4=1, K4 > $N$2), 1, 0) -> 0 | M4: =IF(AND(F4=1, K4 < -$N$2), 1, 0) -> 0 | O4: Best F1
A5: 1 | B5: 1024 | C5: 0.0018 | D5: 1000 | E5: 192 | F5: 0 | G5: 0.99897979 | H5: 0.9959596 | I5: 0.84067789 | J5: =A5 & "_" & B5 & "_" & C5 & "_" & D5 & "_" & E5 -> 1_1024_0.0018_1000_192 | K5: {=IF(F5=1, H5 - _xlfn.XLOOKUP(1, (J:J=J5)*(F:F=0), H:H), _xlfn.XLOOKUP(1, (J:J=J5)*(F:F=1), H:H) - H5 )} -> -0.001010101 | L5: =IF(AND(F5=1, K5 > $N$2), 1, 0) -> 0 | M5: =IF(AND(F5=1, K5 < -$N$2), 1, 0) -> 0 | O5: {=_xlfn.XLOOKUP(MAX(H:H), H:H, A:A:K:K)} -> 1 | P5: 512 | Q5: 0.002 | R5: 1000 | S5: 224 | T5: 0 | U5: 0.99917371 | V5: 0.99882214 | W5: 0.78901706 | X5: 1_512_0.002_1000_224 | Y5: -0.00058996927
A6: 1 | B6: 1024 | C6: 0.002 | D6: 1000 | E6: 192 | F6: 1 | G6: 0.99911318 | H6: 0.99443601 | I6: 0.89491317 | J6: =A6 & "_" & B6 & "_" & C6 & "_" & D6 & "_" & E6 -> 1_1024_0.002_1000_192 | K6: {=IF(F6=1, H6 - _xlfn.XLOOKUP(1, (J:J=J6)*(F:F=0), H:H), _xlfn.XLOOKUP(1, (J:J=J6)*(F:F=1), H:H) - H6 )} -> -0.00050325709 | L6: =IF(AND(F6=1, K6 > $N$2), 1, 0) -> 0 | M6: =IF(AND(F6=1, K6 < -$N$2), 1, 0) -> 0
A7: 1 | B7: 1024 | C7: 0.0025 | D7: 1000 | E7: 192 | F7: 1 | G7: 0.99894948 | H7: 0.99494439 | I7: 0.91041622 | J7: =A7 & "_" & B7 & "_" & C7 & "_" & D7 & "_" & E7 -> 1_1024_0.0025_1000_192 | K7: {=IF(F7=1, H7 - _xlfn.XLOOKUP(1, (J:J=J7)*(F:F=0), H:H), _xlfn.XLOOKUP(1, (J:J=J7)*(F:F=1), H:H) - H7 )} -> -0.0020222447 | L7: =IF(AND(F7=1, K7 > $N$2), 1, 0) -> 0 | M7: =IF(AND(F7=1, K7 < -$N$2), 1, 0) -> 1 | O7: Average AUC with BFW | Q7: Average AUC without BFW | S7: Difference in AUC mean with BFW - without BFW
A8: 1 | B8: 1024 | C8: 0.0025 | D8: 1000 | E8: 192 | F8: 0 | G8: 0.99865996 | H8: 0.99696663 | I8: 0.83641596 | J8: =A8 & "_" & B8 & "_" & C8 & "_" & D8 & "_" & E8 -> 1_1024_0.0025_1000_192 | K8: {=IF(F8=1, H8 - _xlfn.XLOOKUP(1, (J:J=J8)*(F:F=0), H:H), _xlfn.XLOOKUP(1, (J:J=J8)*(F:F=1), H:H) - H8 )} -> -0.0020222447 | L8: =IF(AND(F8=1, K8 > $N$2), 1, 0) -> 0 | M8: =IF(AND(F8=1, K8 < -$N$2), 1, 0) -> 0 | O8: =AVERAGEIF(F:F, 1, G:G) -> 0.97779924 | Q8: =AVERAGEIF(F:F, 0, G:G) -> 0.97712208 | S8: =O8-Q8 -> 0.00067715854
A9: 1 | B9: 1024 | C9: 0.002 | D9: 1000 | E9: 192 | F9: 0 | G9: 0.99899216 | H9: 0.99493927 | I9: 0.83574468 | J9: =A9 & "_" & B9 & "_" & C9 & "_" & D9 & "_" & E9 -> 1_1024_0.002_1000_192 | K9: {=IF(F9=1, H9 - _xlfn.XLOOKUP(1, (J:J=J9)*(F:F=0), H:H), _xlfn.XLOOKUP(1, (J:J=J9)*(F:F=1), H:H) - H9 )} -> -0.00050325709 | L9: =IF(AND(F9=1, K9 > $N$2), 1, 0) -> 0 | M9: =IF(AND(F9=1, K9 < -$N$2), 1, 0) -> 0
A10: 1 | B10: 1024 | C10: 0.0018 | D10: 1000 | E10: 224 | F10: 1 | G10: 0.99930859 | H10: 0.99705015 | I10: 0.87397628 | J10: =A10 & "_" & B10 & "_" & C10 & "_" & D10 & "_" & E10 -> 1_1024_0.0018_1000_224 | K10: {=IF(F10=1, H10 - _xlfn.XLOOKUP(1, (J:J=J10)*(F:F=0), H:H), _xlfn.XLOOKUP(1, (J:J=J10)*(F:F=1), H:H) - H10 )} -> 0 | L10: =IF(AND(F10=1, K10 > $N$2), 1, 0) -> 0 | M10: =IF(AND(F10=1, K10 < -$N$2), 1, 0) -> 0 | O10: AUC Mean T Test p-value | Q10: Percent Improvement in AUC mean with BFW
A11: 1 | B11: 1024 | C11: 0.0018 | D11: 1000 | E11: 224 | F11: 0 | G11: 0.99935244 | H11: 0.99705015 | I11: 0.84357337 | J11: =A11 & "_" & B11 & "_" & C11 & "_" & D11 & "_" & E11 -> 1_1024_0.0018_1000_224 | K11: {=IF(F11=1, H11 - _xlfn.XLOOKUP(1, (J:J=J11)*(F:F=0), H:H), _xlfn.XLOOKUP(1, (J:J=J11)*(F:F=1), H:H) - H11 )} -> 0 | L11: =IF(AND(F11=1, K11 > $N$2), 1, 0) -> 0 | M11: =IF(AND(F11=1, K11 < -$N$2), 1, 0) -> 0 | O11: {=_xlfn.T.TEST(_xlfn._xlws.FILTER(G:G, F:F=1), _xlfn._xlws.FILTER(G:G, F:F=0), 2, 3)} -> 0.97296619 | Q11: =(S8)/Q8*100 -> 0.069301324
A12: 1 | B12: 1024 | C12: 0.002 | D12: 1000 | E12: 224 | F12: 1 | G12: 0.99921923 | H12: 0.99823217 | I12: 0.82159161 | J12: =A12 & "_" & B12 & "_" & C12 & "_" & D12 & "_" & E12 -> 1_1024_0.002_1000_224 | K12: {=IF(F12=1, H12 - _xlfn.XLOOKUP(1, (J:J=J12)*(F:F=0), H:H), _xlfn.XLOOKUP(1, (J:J=J12)*(F:F=1), H:H) - H12 )} -> 0.00058788703 | L12: =IF(AND(F12=1, K12 > $N$2), 1, 0) -> 0 | M12: =IF(AND(F12=1, K12 < -$N$2), 1, 0) -> 0
A13: 1 | B13: 1024 | C13: 0.0025 | D13: 1000 | E13: 224 | F13: 1 | G13: 0.99934667 | H13: 0.99823217 | I13: 0.81894623 | J13: =A13 & "_" & B13 & "_" & C13 & "_" & D13 & "_" & E13 -> 1_1024_0.0025_1000_224 | K13: {=IF(F13=1, H13 - _xlfn.XLOOKUP(1, (J:J=J13)*(F:F=0), H:H), _xlfn.XLOOKUP(1, (J:J=J13)*(F:F=1), H:H) - H13 )} -> 0 | L13: =IF(AND(F13=1, K13 > $N$2), 1, 0) -> 0 | M13: =IF(AND(F13=1, K13 < -$N$2), 1, 0) -> 0 | O13: Average F1 with BFW | Q13: Average F1 without BFW | S13: Difference in F1 mean with BFW - without BFW
A14: 1 | B14: 1024 | C14: 0.0025 | D14: 1000 | E14: 224 | F14: 0 | G14: 0.99948323 | H14: 0.99823217 | I14: 0.80502422 | J14: =A14 & "_" & B14 & "_" & C14 & "_" & D14 & "_" & E14 -> 1_1024_0.0025_1000_224 | K14: {=IF(F14=1, H14 - _xlfn.XLOOKUP(1, (J:J=J14)*(F:F=0), H:H), _xlfn.XLOOKUP(1, (J:J=J14)*(F:F=1), H:H) - H14 )} -> 0 | L14: =IF(AND(F14=1, K14 > $N$2), 1, 0) -> 0 | M14: =IF(AND(F14=1, K14 < -$N$2), 1, 0) -> 0 | O14: =AVERAGEIF(F:F, 1, H:H) -> 0.94583645 | Q14: =AVERAGEIF(F:F, 0, H:H) -> 0.94479022 | S14: =O14-Q14 -> 0.0010462246
A15: 1 | B15: 1024 | C15: 0.002 | D15: 1000 | E15: 224 | F15: 0 | G15: 0.99948581 | H15: 0.99764429 | I15: 0.79248291 | J15: =A15 & "_" & B15 & "_" & C15 & "_" & D15 & "_" & E15 -> 1_1024_0.002_1000_224 | K15: {=IF(F15=1, H15 - _xlfn.XLOOKUP(1, (J:J=J15)*(F:F=0), H:H), _xlfn.XLOOKUP(1, (J:J=J15)*(F:F=1), H:H) - H15 )} -> 0.00058788703 | L15: =IF(AND(F15=1, K15 > $N$2), 1, 0) -> 0 | M15: =IF(AND(F15=1, K15 < -$N$2), 1, 0) -> 0
A16: 1 | B16: 256 | C16: 0.0018 | D16: 1000 | E16: 192 | F16: 1 | G16: 0.99920211 | H16: 0.99645928 | I16: 0.89451035 | J16: =A16 & "_" & B16 & "_" & C16 & "_" & D16 & "_" & E16 -> 1_256_0.0018_1000_192 | K16: {=IF(F16=1, H16 - _xlfn.XLOOKUP(1, (J:J=J16)*(F:F=0), H:H), _xlfn.XLOOKUP(1, (J:J=J16)*(F:F=1), H:H) - H16 )} -> 0 | L16: =IF(AND(F16=1, K16 > $N$2), 1, 0) -> 0 | M16: =IF(AND(F16=1, K16 < -$N$2), 1, 0) -> 0 | O16: F1 Mean T Test p-value | Q16: Percent Improvement in AUC mean with BFW
A17: 1 | B17: 256 | C17: 0.0018 | D17: 1000 | E17: 192 | F17: 0 | G17: 0.99896486 | H17: 0.99645928 | I17: 0.85943136 | J17: =A17 & "_" & B17 & "_" & C17 & "_" & D17 & "_" & E17 -> 1_256_0.0018_1000_192 | K17: {=IF(F17=1, H17 - _xlfn.XLOOKUP(1, (J:J=J17)*(F:F=0), H:H), _xlfn.XLOOKUP(1, (J:J=J17)*(F:F=1), H:H) - H17 )} -> 0 | L17: =IF(AND(F17=1, K17 > $N$2), 1, 0) -> 0 | M17: =IF(AND(F17=1, K17 < -$N$2), 1, 0) -> 0 | O17: {=_xlfn.T.TEST(_xlfn._xlws.FILTER(H:H, F:F=1), _xlfn._xlws.FILTER(H:H, F:F=0), 2, 3)} -> 0.97735324 | Q17: =(S14)/Q14*100 -> 0.11073618
A18: 1 | B18: 256 | C18: 0.002 | D18: 1000 | E18: 192 | F18: 1 | G18: 0.99921604 | H18: 0.99646286 | I18: 0.85355816 | J18: =A18 & "_" & B18 & "_" & C18 & "_" & D18 & "_" & E18 -> 1_256_0.002_1000_192 | K18: {=IF(F18=1, H18 - _xlfn.XLOOKUP(1, (J:J=J18)*(F:F=0), H:H), _xlfn.XLOOKUP(1, (J:J=J18)*(F:F=1), H:H) - H18 )} -> 0.00051144303 | L18: =IF(AND(F18=1, K18 > $N$2), 1, 0) -> 0 | M18: =IF(AND(F18=1, K18 < -$N$2), 1, 0) -> 0
A19: 1 | B19: 256 | C19: 0.0025 | D19: 1000 | E19: 192 | F19: 1 | G19: 0.99883414 | H19: 0.99546142 | I19: 0.86128009 | J19: =A19 & "_" & B19 & "_" & C19 & "_" & D19 & "_" & E19 -> 1_256_0.0025_1000_192 | K19: {=IF(F19=1, H19 - _xlfn.XLOOKUP(1, (J:J=J19)*(F:F=0), H:H), _xlfn.XLOOKUP(1, (J:J=J19)*(F:F=1), H:H) - H19 )} -> -0.001005009 | L19: =IF(AND(F19=1, K19 > $N$2), 1, 0) -> 0 | M19: =IF(AND(F19=1, K19 < -$N$2), 1, 0) -> 0
A20: 1 | B20: 256 | C20: 0.0025 | D20: 1000 | E20: 192 | F20: 0 | G20: 0.99915018 | H20: 0.99646643 | I20: 0.82784415 | J20: =A20 & "_" & B20 & "_" & C20 & "_" & D20 & "_" & E20 -> 1_256_0.0025_1000_192 | K20: {=IF(F20=1, H20 - _xlfn.XLOOKUP(1, (J:J=J20)*(F:F=0), H:H), _xlfn.XLOOKUP(1, (J:J=J20)*(F:F=1), H:H) - H20 )} -> -0.001005009 | L20: =IF(AND(F20=1, K20 > $N$2), 1, 0) -> 0 | M20: =IF(AND(F20=1, K20 < -$N$2), 1, 0) -> 0 | O20: =O7 -> Average AUC with BFW | P20: =Q7 -> Average AUC without BFW | Q20: =S7 -> Difference in AUC mean with BFW - without BFW | R20: =O10 -> AUC Mean T Test p-value | S20: =Q10 -> Percent Improvement in AUC mean with BFW
A21: 1 | B21: 256 | C21: 0.002 | D21: 1000 | E21: 192 | F21: 0 | G21: 0.9985395 | H21: 0.99595142 | I21: 0.86550825 | J21: =A21 & "_" & B21 & "_" & C21 & "_" & D21 & "_" & E21 -> 1_256_0.002_1000_192 | K21: {=IF(F21=1, H21 - _xlfn.XLOOKUP(1, (J:J=J21)*(F:F=0), H:H), _xlfn.XLOOKUP(1, (J:J=J21)*(F:F=1), H:H) - H21 )} -> 0.00051144303 | L21: =IF(AND(F21=1, K21 > $N$2), 1, 0) -> 0 | M21: =IF(AND(F21=1, K21 < -$N$2), 1, 0) -> 0 | O21: =O8 -> 0.97779924 | P21: =Q8 -> 0.97712208 | Q21: =S8 -> 0.00067715854 | R21: =O11 -> 0.97296619 | S21: =Q11 -> 0.069301324
A22: 1 | B22: 256 | C22: 0.0018 | D22: 1000 | E22: 224 | F22: 1 | G22: 0.99916506 | H22: 0.99823217 | I22: 0.81755235 | J22: =A22 & "_" & B22 & "_" & C22 & "_" & D22 & "_" & E22 -> 1_256_0.0018_1000_224 | K22: {=IF(F22=1, H22 - _xlfn.XLOOKUP(1, (J:J=J22)*(F:F=0), H:H), _xlfn.XLOOKUP(1, (J:J=J22)*(F:F=1), H:H) - H22 )} -> 0 | L22: =IF(AND(F22=1, K22 > $N$2), 1, 0) -> 0 | M22: =IF(AND(F22=1, K22 < -$N$2), 1, 0) -> 0
A23: 1 | B23: 256 | C23: 0.0018 | D23: 1000 | E23: 224 | F23: 0 | G23: 0.99936549 | H23: 0.99823217 | I23: 0.82026834 | J23: =A23 & "_" & B23 & "_" & C23 & "_" & D23 & "_" & E23 -> 1_256_0.0018_1000_224 | K23: {=IF(F23=1, H23 - _xlfn.XLOOKUP(1, (J:J=J23)*(F:F=0), H:H), _xlfn.XLOOKUP(1, (J:J=J23)*(F:F=1), H:H) - H23 )} -> 0 | L23: =IF(AND(F23=1, K23 > $N$2), 1, 0) -> 0 | M23: =IF(AND(F23=1, K23 < -$N$2), 1, 0) -> 0
A24: 1 | B24: 256 | C24: 0.002 | D24: 1000 | E24: 224 | F24: 1 | G24: 0.99951828 | H24: 0.99764429 | I24: 0.82929294 | J24: =A24 & "_" & B24 & "_" & C24 & "_" & D24 & "_" & E24 -> 1_256_0.002_1000_224 | K24: {=IF(F24=1, H24 - _xlfn.XLOOKUP(1, (J:J=J24)*(F:F=0), H:H), _xlfn.XLOOKUP(1, (J:J=J24)*(F:F=1), H:H) - H24 )} -> -0.00058788703 | L24: =IF(AND(F24=1, K24 > $N$2), 1, 0) -> 0 | M24: =IF(AND(F24=1, K24 < -$N$2), 1, 0) -> 0
A25: 1 | B25: 256 | C25: 0.0025 | D25: 1000 | E25: 224 | F25: 1 | G25: 0.99938445 | H25: 0.99764151 | I25: 0.85271399 | J25: =A25 & "_" & B25 & "_" & C25 & "_" & D25 & "_" & E25 -> 1_256_0.0025_1000_224 | K25: {=IF(F25=1, H25 - _xlfn.XLOOKUP(1, (J:J=J25)*(F:F=0), H:H), _xlfn.XLOOKUP(1, (J:J=J25)*(F:F=1), H:H) - H25 )} -> -0.00059066499 | L25: =IF(AND(F25=1, K25 > $N$2), 1, 0) -> 0 | M25: =IF(AND(F25=1, K25 < -$N$2), 1, 0) -> 0
A26: 1 | B26: 256 | C26: 0.0025 | D26: 1000 | E26: 224 | F26: 0 | G26: 0.9994544 | H26: 0.99823217 | I26: 0.81984087 | J26: =A26 & "_" & B26 & "_" & C26 & "_" & D26 & "_" & E26 -> 1_256_0.0025_1000_224 | K26: {=IF(F26=1, H26 - _xlfn.XLOOKUP(1, (J:J=J26)*(F:F=0), H:H), _xlfn.XLOOKUP(1, (J:J=J26)*(F:F=1), H:H) - H26 )} -> -0.00059066499 | L26: =IF(AND(F26=1, K26 > $N$2), 1, 0) -> 0 | M26: =IF(AND(F26=1, K26 < -$N$2), 1, 0) -> 0 | O26: =O13 -> Average F1 with BFW | P26: =Q13 -> Average F1 without BFW | Q26: =S13 -> Difference in F1 mean with BFW - without BFW | R26: =O16 -> F1 Mean T Test p-value | S26: =Q16 -> Percent Improvement in AUC mean with BFW
A27: 1 | B27: 256 | C27: 0.002 | D27: 1000 | E27: 224 | F27: 0 | G27: 0.9993579 | H27: 0.99823217 | I27: 0.8116248 | J27: =A27 & "_" & B27 & "_" & C27 & "_" & D27 & "_" & E27 -> 1_256_0.002_1000_224 | K27: {=IF(F27=1, H27 - _xlfn.XLOOKUP(1, (J:J=J27)*(F:F=0), H:H), _xlfn.XLOOKUP(1, (J:J=J27)*(F:F=1), H:H) - H27 )} -> -0.00058788703 | L27: =IF(AND(F27=1, K27 > $N$2), 1, 0) -> 0 | M27: =IF(AND(F27=1, K27 < -$N$2), 1, 0) -> 0 | O27: =O14 -> 0.94583645 | P27: =Q14 -> 0.94479022 | Q27: =S14 -> 0.0010462246 | R27: =O17 -> 0.97735324 | S27: =Q17 -> 0.11073618
A28: 1 | B28: 512 | C28: 0.0005 | D28: 1000 | E28: 64 | F28: 1 | G28: 0.9966217 | H28: 0.93886967 | I28: 0.63757201 | J28: =A28 & "_" & B28 & "_" & C28 & "_" & D28 & "_" & E28 -> 1_512_0.0005_1000_64 | K28: {=IF(F28=1, H28 - _xlfn.XLOOKUP(1, (J:J=J28)*(F:F=0), H:H), _xlfn.XLOOKUP(1, (J:J=J28)*(F:F=1), H:H) - H28 )} -> 0.001308371 | L28: =IF(AND(F28=1, K28 > $N$2), 1, 0) -> 0 | M28: =IF(AND(F28=1, K28 < -$N$2), 1, 0) -> 0
A29: 1 | B29: 512 | C29: 0.0005 | D29: 1000 | E29: 64 | F29: 0 | G29: 0.99659073 | H29: 0.93756129 | I29: 0.61312009 | J29: =A29 & "_" & B29 & "_" & C29 & "_" & D29 & "_" & E29 -> 1_512_0.0005_1000_64 | K29: {=IF(F29=1, H29 - _xlfn.XLOOKUP(1, (J:J=J29)*(F:F=0), H:H), _xlfn.XLOOKUP(1, (J:J=J29)*(F:F=1), H:H) - H29 )} -> 0.001308371 | L29: =IF(AND(F29=1, K29 > $N$2), 1, 0) -> 0 | M29: =IF(AND(F29=1, K29 < -$N$2), 1, 0) -> 0
A30: 1 | B30: 512 | C30: 0.0005 | D30: 200 | E30: 64 | F30: 1 | G30: 0.99627957 | H30: 0.93710178 | I30: 0.73088771 | J30: =A30 & "_" & B30 & "_" & C30 & "_" & D30 & "_" & E30 -> 1_512_0.0005_200_64 | K30: {=IF(F30=1, H30 - _xlfn.XLOOKUP(1, (J:J=J30)*(F:F=0), H:H), _xlfn.XLOOKUP(1, (J:J=J30)*(F:F=1), H:H) - H30 )} -> -0.0032410011 | L30: =IF(AND(F30=1, K30 > $N$2), 1, 0) -> 0 | M30: =IF(AND(F30=1, K30 < -$N$2), 1, 0) -> 1
A31: 1 | B31: 512 | C31: 0.0005 | D31: 200 | E31: 64 | F31: 0 | G31: 0.99670195 | H31: 0.94034278 | I31: 0.63325219 | J31: =A31 & "_" & B31 & "_" & C31 & "_" & D31 & "_" & E31 -> 1_512_0.0005_200_64 | K31: {=IF(F31=1, H31 - _xlfn.XLOOKUP(1, (J:J=J31)*(F:F=0), H:H), _xlfn.XLOOKUP(1, (J:J=J31)*(F:F=1), H:H) - H31 )} -> -0.0032410011 | L31: =IF(AND(F31=1, K31 > $N$2), 1, 0) -> 0 | M31: =IF(AND(F31=1, K31 < -$N$2), 1, 0) -> 0
A32: 1 | B32: 512 | C32: 0.0005 | D32: 1000 | E32: 96 | F32: 1 | G32: 0.99881857 | H32: 0.96684384 | I32: 0.79357818 | J32: =A32 & "_" & B32 & "_" & C32 & "_" & D32 & "_" & E32 -> 1_512_0.0005_1000_96 | K32: {=IF(F32=1, H32 - _xlfn.XLOOKUP(1, (J:J=J32)*(F:F=0), H:H), _xlfn.XLOOKUP(1, (J:J=J32)*(F:F=1), H:H) - H32 )} -> 0.0057078131 | L32: =IF(AND(F32=1, K32 > $N$2), 1, 0) -> 1 | M32: =IF(AND(F32=1, K32 < -$N$2), 1, 0) -> 0
A33: 1 | B33: 512 | C33: 0.0005 | D33: 1000 | E33: 96 | F33: 0 | G33: 0.99860266 | H33: 0.96113602 | I33: 0.74556677 | J33: =A33 & "_" & B33 & "_" & C33 & "_" & D33 & "_" & E33 -> 1_512_0.0005_1000_96 | K33: {=IF(F33=1, H33 - _xlfn.XLOOKUP(1, (J:J=J33)*(F:F=0), H:H), _xlfn.XLOOKUP(1, (J:J=J33)*(F:F=1), H:H) - H33 )} -> 0.0057078131 | L33: =IF(AND(F33=1, K33 > $N$2), 1, 0) -> 0 | M33: =IF(AND(F33=1, K33 < -$N$2), 1, 0) -> 0
A34: 1 | B34: 512 | C34: 0.0005 | D34: 1000 | E34: 128 | F34: 1 | G34: 0.99938154 | H34: 0.97938493 | I34: 0.9361147 | J34: =A34 & "_" & B34 & "_" & C34 & "_" & D34 & "_" & E34 -> 1_512_0.0005_1000_128 | K34: {=IF(F34=1, H34 - _xlfn.XLOOKUP(1, (J:J=J34)*(F:F=0), H:H), _xlfn.XLOOKUP(1, (J:J=J34)*(F:F=1), H:H) - H34 )} -> -0.011502687 | L34: =IF(AND(F34=1, K34 > $N$2), 1, 0) -> 0 | M34: =IF(AND(F34=1, K34 < -$N$2), 1, 0) -> 1
A35: 1 | B35: 512 | C35: 0.0005 | D35: 1000 | E35: 128 | F35: 0 | G35: 0.99966169 | H35: 0.99088761 | I35: 0.82213952 | J35: =A35 & "_" & B35 & "_" & C35 & "_" & D35 & "_" & E35 -> 1_512_0.0005_1000_128 | K35: {=IF(F35=1, H35 - _xlfn.XLOOKUP(1, (J:J=J35)*(F:F=0), H:H), _xlfn.XLOOKUP(1, (J:J=J35)*(F:F=1), H:H) - H35 )} -> -0.011502687 | L35: =IF(AND(F35=1, K35 > $N$2), 1, 0) -> 0 | M35: =IF(AND(F35=1, K35 < -$N$2), 1, 0) -> 0
A36: 1 | B36: 512 | C36: 0.0005 | D36: 200 | E36: 128 | F36: 1 | G36: 0.99928615 | H36: 0.97487437 | I36: 0.8997382 | J36: =A36 & "_" & B36 & "_" & C36 & "_" & D36 & "_" & E36 -> 1_512_0.0005_200_128 | K36: {=IF(F36=1, H36 - _xlfn.XLOOKUP(1, (J:J=J36)*(F:F=0), H:H), _xlfn.XLOOKUP(1, (J:J=J36)*(F:F=1), H:H) - H36 )} -> -0.01227911 | L36: =IF(AND(F36=1, K36 > $N$2), 1, 0) -> 0 | M36: =IF(AND(F36=1, K36 < -$N$2), 1, 0) -> 1
A37: 1 | B37: 512 | C37: 0.0005 | D37: 200 | E37: 128 | F37: 0 | G37: 0.99949695 | H37: 0.98715348 | I37: 0.82418276 | J37: =A37 & "_" & B37 & "_" & C37 & "_" & D37 & "_" & E37 -> 1_512_0.0005_200_128 | K37: {=IF(F37=1, H37 - _xlfn.XLOOKUP(1, (J:J=J37)*(F:F=0), H:H), _xlfn.XLOOKUP(1, (J:J=J37)*(F:F=1), H:H) - H37 )} -> -0.01227911 | L37: =IF(AND(F37=1, K37 > $N$2), 1, 0) -> 0 | M37: =IF(AND(F37=1, K37 < -$N$2), 1, 0) -> 0
A38: 1 | B38: 512 | C38: 0.0005 | D38: 1000 | E38: 160 | F38: 1 | G38: 0.99956081 | H38: 0.98816568 | I38: 0.9561845 | J38: =A38 & "_" & B38 & "_" & C38 & "_" & D38 & "_" & E38 -> 1_512_0.0005_1000_160 | K38: {=IF(F38=1, H38 - _xlfn.XLOOKUP(1, (J:J=J38)*(F:F=0), H:H), _xlfn.XLOOKUP(1, (J:J=J38)*(F:F=1), H:H) - H38 )} -> -0.0051229101 | L38: =IF(AND(F38=1, K38 > $N$2), 1, 0) -> 0 | M38: =IF(AND(F38=1, K38 < -$N$2), 1, 0) -> 1
A39: 1 | B39: 512 | C39: 0.0005 | D39: 1000 | E39: 160 | F39: 0 | G39: 0.99944927 | H39: 0.99328859 | I39: 0.78794408 | J39: =A39 & "_" & B39 & "_" & C39 & "_" & D39 & "_" & E39 -> 1_512_0.0005_1000_160 | K39: {=IF(F39=1, H39 - _xlfn.XLOOKUP(1, (J:J=J39)*(F:F=0), H:H), _xlfn.XLOOKUP(1, (J:J=J39)*(F:F=1), H:H) - H39 )} -> -0.0051229101 | L39: =IF(AND(F39=1, K39 > $N$2), 1, 0) -> 0 | M39: =IF(AND(F39=1, K39 < -$N$2), 1, 0) -> 0
... A69: 1 | B69: 512 | C69: 0.0005 | D69: 200 | E69: 32 | F69: 0 | G69: 0.97902045 | H69: 0.84915836 | I69: 0.4031467 | J69: =A69 & "_" & B69 & "_" & C69 & "_" & D69 & "_" & E69 -> 1_512_0.0005_200_32 | K69: {=IF(F69=1, H69 - _xlfn.XLOOKUP(1, (J:J=J69)*(F:F=0), H:H), _xlfn.XLOOKUP(1, (J:J=J69)*(F:F=1), H:H) - H69 )} -> 0.016278337 | L69: =IF(AND(F69=1, K69 > $N$2), 1, 0) -> 0 | M69: =IF(AND(F69=1, K69 < -$N$2), 1, 0) -> 0
...

Sheet gear
A1: feature extraction | B1: batch size | C1: learning rate | D1: epochs | E1: msg per input | F1: bfw | G1: auc | H1: max f1 | I1: max f1 threshhold | J1: config ID | K1: Tie Threshold | L1: Wins | M1: Loss | O1: Best AUC
A2: 1 | B2: 1024 | C2: 0.0018 | D2: 1000 | E2: 192 | F2: 1 | G2: 0.69599376 | H2: 0.072558858 | I2: 0.37518213 | J2: =A2 & "_" & B2 & "_" & C2 & "_" & D2 & "_" & E2 -> 1_1024_0.0018_1000_192 | K2: {=IF(F2=1, H2 - _xlfn.XLOOKUP(1, (J:J=J2)*(F:F=0), H:H), _xlfn.XLOOKUP(1, (J:J=J2)*(F:F=1), H:H) - H2 )} -> 0.0049128036 | L2: =IF(AND(F2=1, K2 > $N$2), 1, 0) -> 1 | M2: =IF(AND(F2=1, K2 < -$N$2), 1, 0) -> 0 | N2: 0.002 | O2: feature extraction | P2: batch size | Q2: learning rate | R2: epochs | S2: msg per input | T2: bfw | U2: auc | V2: max f1 | W2: max f1 threshhold | X2: config ID | Y2: Tie Threshold
A3: 1 | B3: 1024 | C3: 0.0018 | D3: 1000 | E3: 192 | F3: 1 | G3: 0.69816468 | H3: 0.07310504 | I3: 0.37462275 | J3: =A3 & "_" & B3 & "_" & C3 & "_" & D3 & "_" & E3 -> 1_1024_0.0018_1000_192 | K3: {=IF(F3=1, H3 - _xlfn.XLOOKUP(1, (J:J=J3)*(F:F=0), H:H), _xlfn.XLOOKUP(1, (J:J=J3)*(F:F=1), H:H) - H3 )} -> 0.0054589864 | L3: =IF(AND(F3=1, K3 > $N$2), 1, 0) -> 1 | M3: =IF(AND(F3=1, K3 < -$N$2), 1, 0) -> 0 | O3: {=_xlfn.XLOOKUP(MAX(G:G), G:G, A:A:K:K)} -> 1 | P3: 512 | Q3: 0.002 | R3: 1000 | S3: 256 | T3: 1 | U3: 0.90093119 | V3: 0.21580928 | W3: 0.54480591 | X3: 1_512_0.002_1000_256 | Y3: 0.046099296
A4: 1 | B4: 1024 | C4: 0.0018 | D4: 1000 | E4: 192 | F4: 1 | G4: 0.69927482 | H4: 0.074016962 | I4: 0.37491681 | J4: =A4 & "_" & B4 & "_" & C4 & "_" & D4 & "_" & E4 -> 1_1024_0.0018_1000_192 | K4: {=IF(F4=1, H4 - _xlfn.XLOOKUP(1, (J:J=J4)*(F:F=0), H:H), _xlfn.XLOOKUP(1, (J:J=J4)*(F:F=1), H:H) - H4 )} -> 0.0063709082 | L4: =IF(AND(F4=1, K4 > $N$2), 1, 0) -> 1 | M4: =IF(AND(F4=1, K4 < -$N$2), 1, 0) -> 0 | O4: Best F1
A5: 1 | B5: 1024 | C5: 0.0018 | D5: 1000 | E5: 192 | F5: 0 | G5: 0.68029847 | H5: 0.067646054 | I5: 0.35427338 | J5: =A5 & "_" & B5 & "_" & C5 & "_" & D5 & "_" & E5 -> 1_1024_0.0018_1000_192 | K5: {=IF(F5=1, H5 - _xlfn.XLOOKUP(1, (J:J=J5)*(F:F=0), H:H), _xlfn.XLOOKUP(1, (J:J=J5)*(F:F=1), H:H) - H5 )} -> 0.0049128036 | L5: =IF(AND(F5=1, K5 > $N$2), 1, 0) -> 0 | M5: =IF(AND(F5=1, K5 < -$N$2), 1, 0) -> 0 | O5: {=_xlfn.XLOOKUP(MAX(H:H), H:H, A:A:K:K)} -> 1 | P5: 512 | Q5: 0.002 | R5: 1000 | S5: 256 | T5: 1 | U5: 0.90093119 | V5: 0.21580928 | W5: 0.54480591 | X5: 1_512_0.002_1000_256 | Y5: 0.046099296
A6: 1 | B6: 1024 | C6: 0.002 | D6: 1000 | E6: 192 | F6: 1 | G6: 0.74381815 | H6: 0.085924251 | I6: 0.4375095 | J6: =A6 & "_" & B6 & "_" & C6 & "_" & D6 & "_" & E6 -> 1_1024_0.002_1000_192 | K6: {=IF(F6=1, H6 - _xlfn.XLOOKUP(1, (J:J=J6)*(F:F=0), H:H), _xlfn.XLOOKUP(1, (J:J=J6)*(F:F=1), H:H) - H6 )} -> 0.012973431 | L6: =IF(AND(F6=1, K6 > $N$2), 1, 0) -> 1 | M6: =IF(AND(F6=1, K6 < -$N$2), 1, 0) -> 0
